Workbook

Sheet Caja Chica-Cta.Bco
A3: CONDOMINIO EL FRAMBOYANT | H3: CONDOMINIO EL FRAMBOYANT
A4: Calle 30 de Marzo, Las Terrenas, Samaná, República Dominicana 32200 | H4: Calle 30 de Marzo, Las Terrenas, Samaná, República Dominicana 32200
F6: Periodo de 01/01 hasta 23/03/2024 | M6: Periodo de 01/01 hasta 31/12/2024
B7: Estado CAJA CHICA | I7: Estado Cuenta Bancaria/ Banco Popular
B9: Descripción | C9: Fecha | D9: Tipo | E9: Debito | F9: Credito | I9: Descripción | J9: Fecha | K9: Tipo | L9: Debito | M9: Credito
B10: Saldo balance al 31/12/2023 | C10: 45292 | D10: CA | F10: 38550.46 | I10: Saldo balance al 31/12/2023 | J10: 45292 | K10: BQ | M10: 284157.42
B11: Honorario Administrador Enero 2024 | C11: 45293 | D11: CA | E11: -15000 | I11: Luz y Fuerza Diciembre 2023 | J11: 45296 | K11: BQ | L11: -523.82
B12: INAPA Enero 2024 | C12: 45303 | D12: CA | E12: -3600 | I12: 1 camión del agua – El Flaco | J12: 45296 | K12: BQ | L12: -1500
B13: 2 pastillas de cloro para registro agua pluvial | C13: 45303 | D13: CA | E13: -100 | I13: Impuesto 0.15% DGII | J13: 45296 | K13: BQ | L13: -2.25
B14: Registro acta AGE 12/01 ayuntamiento LT | C14: 45310 | D14: CA | E14: -200 | I14: Rep. cambio de luce spot defectuoso-Crismar | J14: 45302 | K14: BQ | L14: -2140
B15: Recogida basura Enero 2024 | C15: 45322 | D15: CA | E15: -1000 | I15: Impuesto 0.15% DGII | J15: 45302 | K15: BQ | L15: -3.21
B16: Honorario Administrador Febrero 2024 | C16: 45323 | D16: CA | E16: -15000 | I16: Materiales plomería y multa demora A7 – Wilner | J16: 45310 | K16: BQ | L16: -6538.23
B17: Honorario del Alguacil para notificación a A-1 | C17: 45330 | D17: CA | E17: -4000 | I17: Impuesto 0.15% DGII | J17: 45310 | K17: BQ | L17: -9.81
B18: Honorario Administrador para AGE 12-01-2024 | C18: 45331 | D18: CA | E18: -2500 | I18: Interés | J18: 45322 | K18: BQ | M18: 60.02
B19: Reembolso a Jeffrey cargo DGII transf banco – A1 | C19: 45331 | D19: CA | E19: -72.56 | I19: Impuesto | J19: 45322 | K19: BQ | L19: -6
B20: Entrada a caja chica desde cuenta banco | C20: 45334 | D20: CA | F20: 20000 | I20: Pago GUERIN-A1 (47 720,90+72,56) | J20: 45331 | K20: BQ | M20: 47793.46
B21: Pago ENGEL – A5 | C21: 45336 | D21: CA | F21: 15000 | I21: Luz y Fuerza Enero 2024 | J21: 45331 | K21: BQ | L21: -710.7
B22: 2 camiones de séptico | C22: 45337 | D22: CA | E22: -14000 | I22: Retiro para caja chica | J22: 45334 | K22: BQ | L22: -20000
B23: Pago FACQUET – A4 | C23: 45342 | D23: CA | F23: 12230 | I23: Pago ONDELLA – A3 | J23: 45335 | K23: BQ | M23: 24134
B24: Registro acta AGO 13/02 ayuntamiento LT | C24: 45342 | D24: CA | E24: -200 | I24: Pago SANTOS – A6 | J24: 45334 | K24: BQ | M24: 24787
B25: Pago a Jeffrey cargo MoneyGram/Deposito – A2 | C25: 45342 | D25: CA | E25: -1000 | I25: Pago HAZELTINE – A7 | J25: 45338 | K25: BQ | M25: 44170.7
B26: Reembolso a Jeffrey cargo DGII transf banco – A7 | C26: 45343 | D26: CA | E26: -221.59 | I26: Pago GUERIN – A1 | J26: 45339 | K26: BQ | M26: 35005.6
B27: Devolucion Material NCB0400046722 Obra contadores, Decision AGO 13.02.24 orden 7 | C27: 45348 | D27: CA | F27: 36150.69
B28: Recogida basura Febrero 2024 | C28: 45351 | D28: CA | E28: -1000 | I28: Pago METAYER-JEAN – A2 | J28: 45342 | K28: BQ | M28: 38625
B29: Honorario Administrador Marzo 2024 | C29: 45352 | D29: CA | E29: -15000 | I29: Pago HAZELTINE – A7 (26,803.85 + 5,221.59) | J29: 45343 | K29: BQ | M29: 32025.44
B30: Pago ONDELLA – A3 | C30: 45358 | D30: CA | F30: 17600 | I30: Avance 60% trabajo muro exterior – Edison | J30: 45343 | K30: BQ | L30: -126944.4
B31: Pago ENGEL – A5 | C31: 45358 | D31: CA | F31: 8900 | I31: Impuesto 0.15% DGII | J31: 45343 | K31: BQ | L31: -190.42
B32: Pago FACQUET – A4 | C32: 45359 | D32: CA | F32: 6015 | I32: Avance 60% trabajo área séptico – Edison | J32: 45343 | K32: BQ | L32: -82584
B33: Materiales Desague Pluvial NCB0400046722 | C33: 45364 | D33: CA | E33: -21368.35
B34: Honorario Administrador (oficina inapa 2 veces, agua negra) | C34: 45371 | D34: CA | E34: -2500
B35: Limpieza frente a la calle y plantas creciendo en drenaje | C35: 45371 | D35: CA | E35: -500
B36: Materiales Desague Pluvial NCB0400046722 | C36: 45371 | D36: CA | E36: -1351.01
B37: Recogida basura Marzo 2024 | C37: 45373 | D37: CA | E37: -1000 | I37: Impuesto 0.15% DGII | J37: 45343 | K37: BQ | L37: -123.88
B38: Materiales Desague Pluvial NCB0400046722 | C38: 45373 | D38: CA | E38: -219.64
B39: Materiales Desague Pluvial NCB0400046722 | C39: 45374 | D39: CA | E39: -399.02
B40: Pago Eddy septico adjuste presupuesto AGE 12.01.24 | C40: 45376 | D40: CA | E40: -14000 | I40: Interés | J40: 45351 | K40: BQ | M40: 63.95
B41: Materiales Desague Pluvial NCB0400046722 | C41: 45376 | D41: CA | E41: -1543.05
B42: Honorario administrador, reunion ayuntamiento- aguas negras | C42: 45377 | D42: CA | E42: -2500 | I42: Impuesto | J42: 45351 | K42: BQ | L42: -6.4
B43: Mantenimiento y rep. Trabajos emergencia, A-1 | C43: 45377 | D43: CA | E43: -3000 | I43: Pago SANTOS – A6 | J43: 45358 | K43: BQ | M43: 18230.03
B44: Materiales Desague Pluvial NCB0400046722 | C44: 45378 | D44: CA | E44: -702.99
...

Sheet Gastos detallados
A3: CONDOMINIO EL FRAMBOYANT
A4: Calle 30 de Marzo, Las Terrenas, Samaná, República Dominicana 32200
E6: Periodo de 01/01 hasta 31/12/2024
B7: Estado detallados de gastos
B9: INAPA (Contrato 321528) / Agua | C9: Fecha | D9: Monto
B10: 1 Camión de agua (interrupción servicio por averías) | C10: 45296 | D10: 1500
B11: INAPA Enero 2024 | C11: 45303 | D11: 3600
B12: INAPA Febrero 2024 | C12: 45359 | D12: 3600
B13: INAPA Marzo 2024 | C13: 45367 | D13: 3600
B14: INAPA Abril 2024 | C14: 45385 | D14: 3600
B15: 1 Camion de Agua | C15: 45387 | D15: 1000
B16: 1 Camión de agua (interrupción servicio por averías) | C16: 45394 | D16: 1000
B17: 1 Camión de agua (interrupción servicio por averías) | C17: 45397 | D17: 1000
B18: 1 Camión de agua (interrupción servicio por averías) | C18: 45407 | D18: 1000
B19: 1 Camión de agua (interrupción servicio por averías) | C19: 45412 | D19: 1000
B20: 1 Camión de agua (interrupción servicio por averías) | C20: 45413 | D20: 1000
B21: INAPA MAYO 2024 | C21: 45418 | D21: 3600
... B23: INAPA JUNIO 2024 | C23: 45455 | D23: 3600
B24: Total | D24: =SUM(D10:D23) -> 30100
B26: LUZ Y FUERZA / Electricidad | C26: Fecha | D26: Monto
B27: Luz Diciembre 2023 (55 kwh) | C27: 45296 | D27: 523.82
B28: Luz Enero 2024 (80 kwh) | C28: 45331 | D28: 710.7
B29: Luz Febrero 2024 (107 kwh) | C29: 45359 | D29: 912.52
B30: Luz Marzo 2024 (176 kwh) | C30: 45385 | D30: 1428.3
B31: Luz Abril 2024 (112 kwh) | C31: 45418 | D31: 949.9
B32: Total | D32: =SUM(D27:D31) -> 4525.24
B34: Cargos Bancario / Banco Popular | C34: Fecha | D34: Monto
B35: Impuesto 0.15% DGII | C35: 45296 | D35: 2.25
B36: Impuesto 0.15% DGII | C36: 45302 | D36: 3.21
B37: Impuesto 0.15% DGII | C37: 45310 | D37: 9.81
B38: Interés | C38: 45322 | D38: -60.02
B39: Impuesto | C39: 45322 | D39: 6
B40: Impuesto 0.15% DGII | C40: 45343 | D40: 190.42
B41: Impuesto 0.15% DGII | C41: 45343 | D41: 123.88
B42: Interés | C42: 45351 | D42: -63.95
B43: Impuesto | C43: 45351 | D43: 6.4
B44: Impuesto 0.15% DGII | C44: 45359 | D44: 5.4
B45: Impuesto 0.15% DGII | C45: 45363 | D45: 19.89
B46: Impuesto 0.15% DGII | C46: 45367 | D46: 63.47
... B64: Impuesto 0.15% DGII | C64: 45461 | D64: 55
...

Sheet PedidoAGE12-01
A3: CONDOMINIO EL FRAMBOYANT
A4: Calle 30 de Marzo, Las Terrenas, Samaná, República Dominicana 32200
F6: Cuota Extraordinaria del 2024
B7: Pedido de fondo para Trabajos decidido en AGE 12/01/2024
E9: Total
B11: Trabajo elevación de nivel área de los sépticos | E11: 124000
B12: Asamblea General Extraordinaria punto 4 (aprobado unanimidad)
B13: Voto electrónico realizado durante 19/01 - 24/01/2024 (100% de emitidos : A2/A3/A6/A7)
B15: Trabajo registro de aguas pluviales subterráneos | E15: 17647.18
B16: Asamblea General Extraordinaria punto 5 (aprobado unanimidad)
B17: Voto electrónico realizado durante 19/01 - 24/01/2024 (100% de emitidos : A2/A3/A6/A7)
B19: *Honorarios 10% para seguimientos y supervisores de trabajos | E19: =(E11+E15)*0.1 -> 14164.718
D21: Monto total | E21: =SUM(E10:E20) -> 155811.9
B22: Notas;
B23: Esta cuota extraordinaria es la manera provisional (presupuestos).
B24: La cierre contable del ejercicio 2024 concluirá una vez que se apruebe en la Asamblea General
B25: Ordinaria del principio 2025.
B27: Les pedimos de realizar su pago lo antes posible.
B28: Les recordamos que tiene 15 días de pagar, en contrario 2% de mora será aplicado.
B30: Repartición de Cuota Extraordianaria AGE 12-01-2024 | E30: =E21 -> 155811.9 | H30: Unidad | I30: Total monto | J30: Valor RD$ | K30: Total valor RD$ | L30: Repartición % | M30: Monto/cada
B31: Propietario | C31: UNIDAD | D31: % | E31: Monto a pagar | H31: 1 | I31: =E30 -> 155811.9 | J31: 3386200 | K31: 26236200 | L31: =(J31/J38)*100 -> 12.906595 | M31: =(I31*J31/K31) -> 20110.01 | N31: 20110.01
B32: Serge GUERRIN | C32: A-1 | D32: 0.1291 | E32: 20110.01 | H32: 2 | I32: =E30 -> 155811.9 | J32: 3453400 | K32: 26236200 | L32: =(J32/J38)*100 -> 13.162729 | M32: =(I32*J32/K32) -> 20509.098 | N32: 20509.1
B33: Hervé METAYER | C33: A-2 | D33: 0.1316 | E33: 20509.1 | H33: 3 | I33: =E30 -> 155811.9 | J33: 4063600 | K33: 26236200 | L33: =(J33/J38)*100 -> 15.488523 | M33: =(I33*J33/K33) -> 24132.962 | N33: 24132.96
B34: Frédéric ONDELLA | C34: A-3 | D34: 0.1549 | E34: 24132.96 | H34: 4 | I34: =E30 -> 155811.9 | J34: 2061000 | K34: 26236200 | L34: =(J34/J38)*100 -> 7.8555584 | M34: =(I34*J34/K34) -> 12239.895 | N34: 12239.9
B35: Patricia FACQUET | C35: A-4 | D35: 0.0786 | E35: 12239.9 | H35: 5 | I35: =E30 -> 155811.9 | J35: 2540000 | K35: 26236200 | L35: =(J35/J38)*100 -> 9.6812801 | M35: =(I35*J35/K35) -> 15084.586 | N35: 15084.59
B36: Gernot ENGER | C36: A-5 | D36: 0.0968 | E36: 15084.59 | H36: 6 | I36: =E30 -> 155811.9 | J36: 4173600 | K36: 26236200 | L36: =(J36/J38)*100 -> 15.907792 | M36: =(I36*J36/K36) -> 24786.232 | N36: 24786.23
B37: Inversiones Ter 187 eirl (Karina SANTOS) | C37: A-6 | D37: 0.1591 | E37: 24786.23 | H37: 7 | I37: =E30 -> 155811.9 | J37: 6558400 | K37: 26236200 | L37: =(J37/J38)*100 -> 24.997523 | M37: =(I37*J37/K37) -> 38949.114 | N37: 38949.11
B38: Jonathan HAZELTINE | C38: A-7 | D38: 0.25 | E38: 38949.11 | J38: =SUM(J31:J37) -> 26236200 | L38: =SUM(L31:L37) -> 100 | M38: =SUM(M31:M37) -> 155811.9 | N38: =SUM(N31:N37) -> 155811.9
B39: Total | D39: =SUM(D32:D38) -> 1.0001 | E39: =SUM(E32:E38) -> 155811.9

Sheet PedidoVotoElec-09-04
A3: CONDOMINIO EL FRAMBOYANT
A4: Calle 30 de Marzo, Las Terrenas, Samaná, República Dominicana 32200
F6: Cuota Extraordinaria del 2024
B7: Pedido de fondo para Trabajos decidido en Voto electronico Del 09-04-2024
E9: Total
B10: Obra 1:
B11: Trabajo Pintura pared cerca entre el terreno al Norte y A-3-Parqueo A3 ambos lados | E11: 19220
B13: *Honorarios 10% para seguimientos y supervisores de trabajos | E13: =E11*0.1 -> 1922
B15: Obra 2:
B16: Dos parillas de metal para el pasaje porton principal y entrada A2-A3 | E16: 57000
D21: Monto total | E21: =SUM(E10:E20) -> 78142
B22: Notas;
B23: Esta cuota extraordinaria es la manera provisional (presupuestos).
B24: La cierre contable del ejercicio 2024 concluirá una vez que se apruebe en la Asamblea General
B25: Ordinaria del principio 2025.
B27: Les pedimos de realizar su pago lo antes posible.
B28: Les recordamos que tiene 15 días de pagar, en contrario 2% de mora será aplicado.
B30: Repartición de Cuota Extraordianaria Voto electronico del 09-04-24 | E30: =E21 -> 78142 | H30: Unidad | I30: Total monto | J30: Valor RD$ | K30: Total valor RD$ | L30: Repartición % | M30: Monto/cada
B31: Propietario | C31: UNIDAD | D31: % | E31: Monto a pagar | H31: 1 | I31: =E30 -> 78142 | J31: 3385038.8 | K31: 26236200 | L31: =J31/J38*100 -> 12.902169 | M31: =(I31*J31/K31) -> 10082.013 | N31: =M31 -> 10082.013
B32: Serge GUERRIN | C32: A-1 | D32: 0.129 | E32: =M31 -> 10082.013 | H32: 2 | I32: =E30 -> 78142 | J32: 3452215.8 | K32: 26236200 | L32: =J32/J38*100 -> 13.158216 | M32: =(I32*J32/K32) -> 10282.093 | N32: =M32 -> 10282.093
B33: Hervé METAYER | C33: A-2 | D33: 0.1316 | E33: =M32 -> 10282.093 | H33: 3 | I33: =E30 -> 78142 | J33: 4062206.5 | K33: 26236200 | L33: =J33/J38*100 -> 15.483212 | M33: =(I33*J33/K33) -> 12098.892 | N33: =M33 -> 12098.892
B34: Frédéric ONDELLA | C34: A-3 | D34: 0.1548 | E34: =M33 -> 12098.892 | H34: 4 | I34: =E30 -> 78142 | J34: 2069290.2 | K34: 26236200 | L34: =J34/J38*100 -> 7.8871565 | M34: =(I34*J34/K34) -> 6163.1818 | N34: =M34 -> 6163.1818
B35: Patricia FACQUET | C35: A-4 | D35: 0.0789 | E35: =M34 -> 6163.1818 | H35: 5 | I35: =E30 -> 78142 | J35: 2539129 | K35: 26236200 | L35: =J35/J38*100 -> 9.6779602 | M35: =(I35*J35/K35) -> 7562.5516 | N35: =M35 -> 7562.5516
B36: Gernot ENGER | C36: A-5 | D36: 0.0968 | E36: =M35 -> 7562.5516 | H36: 6 | I36: =E30 -> 78142 | J36: 4172168.8 | K36: 26236200 | L36: =J36/J38*100 -> 15.902336 | M36: =(I36*J36/K36) -> 12426.404 | N36: =M36 -> 12426.404
B37: Inversiones Ter 187 eirl (Karina SANTOS) | C37: A-6 | D37: 0.159 | E37: =M36 -> 12426.404 | H37: 7 | I37: =E30 -> 78142 | J37: 6556151 | K37: 26236200 | L37: =J37/J38*100 -> 24.98895 | M37: =(I37*J37/K37) -> 19526.866 | N37: =M37 -> 19526.866
B38: Jonathan HAZELTINE | C38: A-7 | D38: 0.2499 | E38: =M37 -> 19526.866 | J38: =SUM(J31:J37) -> 26236200 | L38: =SUM(L31:L37) -> 100 | M38: =SUM(M31:M37) -> 78142 | N38: =SUM(N31:N37) -> 78142
B39: Total | D39: =SUM(D32:D38) -> 1 | E39: =SUM(E32:E38) -> 78142

Sheet Presupuesto 2024 Aprobado
A2: CONDOMINIO EL FRAMBOYANT
A3: Calle 30 de Marzo, Las Terrenas, Samaná, República Dominicana 32200
F5: Periodo de 01/01 hasta 31/12/2024
B6: Presupuesto Provisional 2024 aprobado por la AGO del 13/02/2024
C8: Por mes | D8: Meses | E8: Anual
B9: INAPA/Agua | C9: 3600 | D9: 12 | E9: =C9*D9 -> 43200
B10: Agua (camión de agua) | C10: 1500 | D10: 12 | E10: =C10*D10 -> 18000
B11: LUZ Y FUERZA / Electricidad | C11: 800 | D11: 12 | E11: =C11*D11 -> 9600
B12: Reparaciones / Mantenimientos | C12: 3500 | D12: 12 | E12: =C12*D12 -> 42000
B13: Basura / Recogida mensual | C13: 1000 | D13: 12 | E13: =C13*D13 -> 12000
B14: Honorario Administrador | C14: 15000 | D14: 12 | E14: =C14*D14 -> 180000
B15: Gastos bancario | C15: 150 | D15: 12 | E15: =C15*D15 -> 1800
B16: Trabajo tuberías drenaje de agua pluvial (monto adicional) | E16: 30237.82
B17: Seguro Incendio y R.C. (20/11/2024-2025) | E17: 162400
B18: Total Anual Gastos Provisional 2024 | C18: =SUM(C9:C17) -> 25550 | E18: =SUM(E9:E17) -> 499237.82
B19: Fondo de Reservas (para completar $80,000) | E19: 16030.55
B20: * Fondo de Reservas (diferencia prevista por cancelación trabajo medidor de agua) | C20: (* La diferencia exacta será tomada cuenta al cierre del año 2024) | E20: 23969.45
B21: Total Fondo de Reservas 2024 | E21: =E19+E20 -> 40000
E22: =E18+E21 -> 539237.82
B23: Se pedirá trimestralmente (4 veces) : $124,809.46RD y $10,000.00RD Total $134,809.46RD
B24: Nota: Tenemos una nota de crédito (materiales) con Ferretería The Home Acosta Polanco
B25: con un importe de $14,514.18RD (aproximadamente) | H25: Calculo presupuesto 2024
B26: Repartición de gasto común provisional 2024: | D26: por año | E26: =E18 -> 499237.82 | H26: Unidad | I26: Total monto | J26: Valor RD$ | K26: Total valor RD$ | L26: Repartición % | M26: Monto/cada
B27: Propietario | C27: UNIDAD | D27: % | E27: Monto a pagar | H27: 1 | I27: =E26 -> 499237.82 | J27: 3386200 | K27: 26236200 | L27: =(J27/J34)*100 -> 12.906595 | M27: =(I27*J27/K27) -> 64434.602 | N27: 64434.6
B28: Serge GUERRIN | C28: A-1 | D28: 0.129 | E28: 64434.6 | H28: 2 | I28: =E26 -> 499237.82 | J28: 3453400 | K28: 26236200 | L28: =(J28/J34)*100 -> 13.162729 | M28: =(I28*J28/K28) -> 65713.323 | N28: 65713.32
B29: Herve METAYER | C29: A-2 | D29: 0.1316 | E29: 65713.32 | H29: 3 | I29: =E26 -> 499237.82 | J29: 4063600 | K29: 26236200 | L29: =(J29/J34)*100 -> 15.488523 | M29: =(I29*J29/K29) -> 77324.567 | N29: 77324.57
B30: Frédéric ONDELLA | C30: A-3 | D30: 0.1549 | E30: 77324.57 | H30: 4 | I30: =E26 -> 499237.82 | J30: 2061000 | K30: 26236200 | L30: =(J30/J34)*100 -> 7.8555584 | M30: =(I30*J30/K30) -> 39217.918 | N30: 39217.92
B31: Patricia FACQUET | C31: A-4 | D31: 0.0786 | E31: 39217.92 | H31: 5 | I31: =E26 -> 499237.82 | J31: 2540000 | K31: 26236200 | L31: =(J31/J34)*100 -> 9.6812801 | M31: =(I31*J31/K31) -> 48332.612 | N31: 48332.61
B32: Gernot ENGER | C32: A-5 | D32: 0.0968 | E32: 48332.61 | H32: 6 | I32: =E26 -> 499237.82 | J32: 4173600 | K32: 26236200 | L32: =(J32/J34)*100 -> 15.907792 | M32: =(I32*J32/K32) -> 79417.712 | N32: 79417.71
B33: Inversiones Ter 187 eirl (Karina SANTOS) | C33: A-6 | D33: 0.1591 | E33: 79417.71 | H33: 7 | I33: =E26 -> 499237.82 | J33: 6558400 | K33: 26236200 | L33: =(J33/J34)*100 -> 24.997523 | M33: =(I33*J33/K33) -> 124797.09 | N33: 124797.09
B34: Jonathan HAZELTINE | C34: A-7 | D34: 0.25 | E34: 124797.09 | J34: =SUM(J27:J33) -> 26236200 | L34: =SUM(L27:L33) -> 100 | M34: =SUM(M27:M33) -> 499237.82 | N34: =SUM(N27:N33) -> 499237.82
B35: Total | D35: =SUM(D28:D34) -> 1 | E35: =SUM(E28:E34) -> 499237.82
H36: Calculo Fondo de Reservas 2024
B37: Repartición de Fondo de Reservas 2024: | D37: por año | E37: =E19+E20 -> 40000 | H37: Unidad | I37: Total monto | J37: Valor RD$ | K37: Total valor RD$ | L37: Repartición % | M37: Monto/cada
B38: Propietario | C38: UNIDAD | D38: % | E38: Monto a pagar | H38: 1 | I38: =E37 -> 40000 | J38: 3386200 | K38: 26236200 | L38: =(J38/J45)*100 -> 12.906595 | M38: =(I38*J38/K38) -> 5162.6379 | N38: 5162.64
B39: Serge GUERRIN | C39: A-1 | D39: 0.129 | E39: 5162.64 | H39: 2 | I39: =E37 -> 40000 | J39: 3453400 | K39: 26236200 | L39: =(J39/J45)*100 -> 13.162729 | M39: =(I39*J39/K39) -> 5265.0917 | N39: 5265.09
B40: Herve METAYER | C40: A-2 | D40: 0.1316 | E40: 5265.09 | H40: 3 | I40: =E37 -> 40000 | J40: 4063600 | K40: 26236200 | L40: =(J40/J45)*100 -> 15.488523 | M40: =(I40*J40/K40) -> 6195.4094 | N40: 6195.41
B41: Frédéric ONDELLA | C41: A-3 | D41: 0.1549 | E41: 6195.41 | H41: 4 | I41: =E37 -> 40000 | J41: 2061000 | K41: 26236200 | L41: =(J41/J45)*100 -> 7.8555584 | M41: =(I41*J41/K41) -> 3142.2233 | N41: 3142.22
B42: Patricia FACQUET | C42: A-4 | D42: 0.0786 | E42: 3142.22 | H42: 5 | I42: =E37 -> 40000 | J42: 2540000 | K42: 26236200 | L42: =(J42/J45)*100 -> 9.6812801 | M42: =(I42*J42/K42) -> 3872.512 | N42: 3872.51
B43: Gernot ENGER | C43: A-5 | D43: 0.0968 | E43: 3872.51 | H43: 6 | I43: =E37 -> 40000 | J43: 4173600 | K43: 26236200 | L43: =(J43/J45)*100 -> 15.907792 | M43: =(I43*J43/K43) -> 6363.1166 | N43: 6363.12
...

Sheet A1
A3: CONDOMINIO EL FRAMBOYANT
A4: Calle 30 de Marzo, Las Terrenas, Samaná, República Dominicana 32200
B5: Apartamento A-1
B6: Serge GUERIN | C6: Fecha limite de pago : 17.07.24
B7: serge47.guerin@gmail.com
G9: Periodo de 01/01/2024 hasta 15/04/2024
B10: Estado de cuenta
B12: Descripción | C12: Fecha | D12: Débito | E12: Crédito | F12: Saldo
B13: Pago Serge GUERIN | C13: 45117 | E13: 5900 | F13: =E13 -> 5900
B14: Pago Serge GUERIN | C14: 45117 | E14: 5901 | F14: =F13-D14+E14 -> 11801
B15: Pago Serge GUERIN | C15: 45205 | E15: 25100 | F15: =F14-D15+E15 -> 36901
B16: Pago Serge GUERIN | C16: 45266 | E16: 48373 | F16: =F15-D16+E16 -> 85274
B17: Pago Serge GUERIN | C17: 45266 | E17: 1341 | F17: =F16-D17+E17 -> 86615
B18: Cargo 2% del $26 548.93 (Reglamento Art.33-d) | C18: 45266 | D18: 530.98 | F18: =F17-D18+E18 -> 86084.02
B19: SALDO ANTERIOR | C19: 45657 | F19: 86084.02
B20: Cargo 2% del $26 548.93 (Reglamento Art.33-d) | C20: 45297 | D20: 530.98 | F20: =F18-D20+E20 -> 85553.04
B21: Pedido de fondo – cuota extraordinaria AGE del 12-01-2024 | C21: 45321 | D21: 20110.01 | F21: =F20-D21+E21 -> 65443.03
B22: Honorario del Alguacil LT para la Notificación de deudas | C22: 45330 | D22: 4000 | F22: =F21-D22+E22 -> 61443.03
B23: Pago Serge GUERIN (47 720,90+72,56) | C23: 45331 | E23: 47720.9 | F23: =F22-D23+E23 -> 109163.93
B24: Gastos Total año 2023 (Aprobado en AGO del 13 febrero 2024) | C24: 45335 | D24: 104280.83 | F24: =F23-D24+E24 -> 4883.1
B25: Fondo de Reservas 2023 (Pedido del 01/10/2023 - Total $40,000RD) | C25: 45335 | D25: 5162.64 | F25: =F24-D25+E25 -> -279.54
B26: 1er Trimestre 2024 (Enero – Marzo) / Gastos común provisional | C26: 45336 | D26: 16108.65 | F26: =F25-D26+E26 -> -16388.19
B27: 1er Trimestre 2024 (Enero – Marzo) / Fondo de Reservas 2024 | C27: 45336 | D27: 1290.66 | F27: =F26-D27+E27 -> -17678.85
B28: Pago Serge GUERIN | C28: 45339 | E28: 35005.6 | F28: =F27-D28+E28 -> 17326.75
B29: Rectificación error del 09/02/2024 | C29: 45343 | E29: 72.56 | F29: =F28-D29+E29 -> 17399.31
B30: 2do Trimestre 2024 (Abril – Junio) / Gastos común provisional | C30: 45383 | D30: 16108.65 | F30: =F29-D30+E30 -> 1290.66
B31: 2do Trimestre 2024 (Abril – Junio) / Fondo de Reservas 2024 | C31: 45383 | D31: 1290.66 | F31: =F30-D31+E31 -> 1.978151e-11
B32: Pedido de fondo – cuota extraordinaria Voto electronico del 09-04-2024 | C32: 45397 | D32: 10082.013 | F32: =F31-D32+E32 -> -10082.013
B33: Cargo 2% del $10,082.01 (Reglamento Art.33-d) | C33: 45418 | D33: =D32*2% -> 201.64025 | F33: =F32-D33+E33 -> -10283.653
B34: Cargo administrador recordatorio pago 15 dias despues venc. | C34: 45418 | D34: 1000 | F34: =F33-D34+E34 -> -11283.653
B35: Cargo 2% del $10,082.01 (Reglamento Art.33-d) | C35: 45449 | D35: =D32*2% -> 201.64025 | F35: =F34-D35+E35 -> -11485.293
B36: Cargo administrador segundo recordatorio pago 45 dias despues venc. (cuota 09.04.2024) | C36: 45473 | D36: 3000 | F36: =F35-D36+E36 -> -14485.293
B37: 3er Trimestre 2024 (Julio– Septiembre) / Gastos común provisional | C37: 45474 | D37: ='Presupuesto 2024 Aprobado'!C50 -> 16108.65 | F37: =F36-D37+E37 -> -30593.943
B38: 3er Trimestre 2024 (Julio– Septiembre) / Fondo de Reservas 2024 | C38: 45474 | D38: ='Presupuesto 2024 Aprobado'!D50 -> 1290.66 | F38: =F37-D38+E38 -> -31884.603
C39: TOTAL A1-GUERRIN | D39: =SUM(D13:D38) -> 201298.66 | E39: =SUM(E13:E38) -> 169414.06 | F39: =E39-D39 -> -31884.603
B42: GASTOS PRIVADO - Aparte de los gastos comunes
B43: Diferencia presupuesto pared cerca y gastos reales de la | C43: 45425 | D43: -24574
B44: obra al gasto unico A1-AGE 12.01.24 orden 6
B45: Cargo 2% de $24,574 (Reglamento Art.33-d) | C45: 45443 | D45: =D43*2% -> -491.48
B46: Cargo administrador recordatorio pago 15 dias despues venc. | C46: 45443 | D46: -1000
...

Sheet A2
A3: CONDOMINIO EL FRAMBOYANT
A4: Calle 30 de Marzo, Las Terrenas, Samaná, República Dominicana 32200
B5: Apartamento A-2
B6: Hervé METAYER / Corine JEAN | D6: Fecha limite de pago : 17.07.24
B7: hmetayer.business@gmail.com; corine.2021@outlook.fr
G9: Periodo de 01/01/2024 hasta 15/04/2024
B10: Estado de cuenta
B12: Descripción | C12: Fecha | D12: Débito | E12: Crédito | F12: Saldo
B13: Pago METAYER-JEAN | C13: 45117 | E13: 5900 | F13: =E13 -> 5900
B14: Pago METAYER-JEAN | C14: 45117 | E14: 6015 | F14: =F13-D14+E14 -> 11915
B15: Pago METAYER-JEAN | C15: 45210 | E15: 25600 | F15: =F14-D15+E15 -> 37515
B16: Pago METAYER-JEAN | C16: 45262 | E16: 78000 | F16: =F15-D16+E16 -> 115515
B17: SALDO ANTERIOR | C17: 45291 | F17: =F16-D17+E17 -> 115515
B18: Pedido de fondo – cuota extraordinaria AGE del 12-01-2024 | C18: 45321 | D18: 20509.1 | F18: =F17-D18+E18 -> 95005.9
B19: Gastos Total año 2023 (Aprobado en AGO del 13 febrero 2024) | C19: 45335 | D19: 106350.31 | F19: =F18-D19+E19 -> -11344.41
B20: Fondo de Reservas 2023 (Pedido del 01/10/2023 - Total $40,000RD) | C20: 45335 | D20: 5265.09 | F20: =F19-D20+E20 -> -16609.5
B21: 1er Trimestre 2024 (Enero – Marzo) / Gastos común provisional | C21: 45336 | D21: 16428.33 | F21: =F20-D21+E21 -> -33037.83
B22: 1er Trimestre 2024 (Enero – Marzo) / Fondo de Reservas 2024 | C22: 45336 | D22: 1316.27 | F22: =F21-D22+E22 -> -34354.1
B23: Pago METAYER-JEAN | C23: 45342 | E23: 38625 | F23: =F22-D23+E23 -> 4270.9
B24: Cargo MoneyGram/Deposito Banco-Gasto Personal-A2 | C24: 45342 | D24: 1000 | F24: =F23-D24+E24 -> 3270.9
B25: 2do Trimestre 2024 (Abril – Junio) / Gastos común provisional | C25: 45397 | D25: 16428.33 | E25: 3270.9 | F25: =F24-D25+E25 -> -9886.53
B26: 2do Trimestre 2024 (Abril – Junio) / Fondo de Reservas 2024 | C26: 45397 | D26: 1316.2725 | F26: =F25-D26+E26 -> -11202.803
B27: Pedido de fondo – cuota extraordinaria Voto electronico del 09-04-2024 | C27: 45397 | D27: 10282.093 | F27: =F26-D27+E27 -> -21484.895
B28: Pago METAYER-JEAN | C28: 45408 | E28: 22556.56 | F28: =F27-D28+E28 -> 1071.6647
B29: 3er Trimestre 2024 (Julio– Septiembre) / Gastos común provisional | C29: 45474 | D29: ='Presupuesto 2024 Aprobado'!C51 -> 16428.33 | F29: =F28-D29+E29 -> -15356.665
B30: 3er Trimestre 2024 (Julio– Septiembre) / Fondo de Reservas 2024 | C30: 45474 | D30: ='Presupuesto 2024 Aprobado'!D51 -> 1316.2725 | F30: =F29-D30+E30 -> -16672.938
C31: TOTAL A2-METAYER | D31: =SUM(D13:D30) -> 196640.4 | E31: =SUM(E13:E30) -> 179967.46 | F31: =E31-D31 -> -16672.938
B33: GASTOS PRIVADO - Aparte de los gastos comunes
B34: Cargo MoneyGram/Deposito Banco | D34: -1000 | F34: =F31+D33+D34 -> -17672.938
F35: TOTAL en Crédito
B36: Nota Importante:
B37: Su estado de cuenta está en manera provisional hasta que se cierran las contabilidades del 2024.
B39: Banco POPULAR
B40: Cuenta Corriente - Sra YUNAIRY ENCARNACION - Cedula 134-0005411-3
B41: Cuenta : 0839787280
B42: Pesos

Sheet A3
A3: CONDOMINIO EL FRAMBOYANT
A4: Calle 30 de Marzo, Las Terrenas, Samaná, República Dominicana 32200
B5: Apartamento A3
B6: Frédéric ONDELLA | D6: Fecha limite de pago : 17.07.24
B7: ondellaf@yahoo.fr
G9: Periodo de 01/05/2023 hasta 31/03/2024
B10: Estado de cuenta
B12: Descripción | C12: Fecha | D12: Débito | E12: Crédito | F12: Saldo
B13: Pago Frédéric ONDELLA | C13: 45111 | E13: 7080 | F13: =E13 -> 7080
B14: Pago Frédéric ONDELLA | C14: 45117 | E14: 5900 | F14: =F13-D14+E14 -> 12980
B15: Pago Frédéric ONDELLA | C15: 45219 | E15: 30110 | F15: =F14-D15+E15 -> 43090
B16: Pago Frédéric ONDELLA | C16: 45238 | E16: 88000 | F16: =F15-D16+E16 -> 131090
B17: Pago Frédéric ONDELLA | C17: 45250 | E17: 3530 | F17: =F16-D17+E17 -> 134620
B18: SALDO ANTERIOR | C18: 45291 | F18: =F17-D18+E18 -> 134620
B19: Pedido de fondo – cuota extraordinaria AGE del 12-01-2024 | C19: 45321 | D19: 24132.96 | F19: =F18-D19+E19 -> 110487.04
B20: Pago Frédéric ONDELLA | C20: 45335 | E20: 24134 | F20: =F19-D20+E20 -> 134621.04
B21: Gastos Total año 2023 (Aprobado en AGO del 13 febrero 2024) | C21: 45335 | D21: 125141.93 | F21: =F20-D21+E21 -> 9479.11
B22: Fondo de Reservas 2023 (Pedido del 01/10/2023 - Total $40,000RD) | C22: 45335 | D22: 6195.41 | F22: =F21-D22+E22 -> 3283.7
B23: 1er Trimestre 2024 (Enero – Marzo) / Gastos común provisional | C23: 45336 | D23: 19331.14 | F23: =F22-D23+E23 -> -16047.44
B24: 1er Trimestre 2024 (Enero – Marzo) / Fondo de Reservas 2024 | C24: 45336 | D24: 1548.85 | F24: =F23-D24+E24 -> -17596.29
B25: Pago Frédéric ONDELLA | C25: 45358 | E25: 17600 | F25: =F24-D25+E25 -> 3.71
B26: 2do Trimestre 2024 (Abril – Junio) / Gastos común provisional | C26: 45397 | D26: 19331.143 | F26: =F25-D26+E26 -> -19327.432
B27: 2do Trimestre 2024 (Abril – Junio) / Fondo de Reservas 2024 | C27: 45397 | D27: 1548.8525 | F27: =F26-D27+E27 -> -20876.285
B28: Pedido de fondo – cuota extraordinaria Voto electronico del 09-04-2024 | C28: 45397 | D28: 12098.892 | F28: =F27-D28+E28 -> -32975.177
B29: Pago Frédéric ONDELLA | C29: 45412 | E29: 33000 | F29: =F28-D29+E29 -> 24.823347
B30: 3er Trimestre 2024 (Julio– Septiembre) / Gastos común provisional | C30: 45474 | D30: ='Presupuesto 2024 Aprobado'!C52 -> 19331.143 | F30: =F29-D30+E30 -> -19306.319
B31: 3er Trimestre 2024 (Julio– Septiembre) / Fondo de Reservas 2024 | C31: 45474 | D31: ='Presupuesto 2024 Aprobado'!D52 -> 1548.8525 | F31: =F30-D31+E31 -> -20855.172
C32: TOTAL A3-ONDELLA | D32: =SUM(D13:D31) -> 230209.17 | E32: =SUM(E13:E31) -> 209354 | F32: =E32-D32 -> -20855.172
B34: Nota Importante:
B35: Su estado de cuenta está en manera provisional hasta que se cierran las contabilidades del 2024.
B37: Banco POPULAR
B38: Cuenta Corriente - Sra YUNAIRY ENCARNACION - Cedula 134-0005411-3
B39: Cuenta : 0839787280
B40: Pesos

Sheet A4
A3: CONDOMINIO EL FRAMBOYANT
A4: Calle 30 de Marzo, Las Terrenas, Samaná, República Dominicana 32200
B5: Apartamento A-4
B6: Patricia FACQUET | D6: Fecha limite de pago : 17.07.24
B7: patriciafacquet@icloud.com
G9: Periodo de 01/01/2024 hasta 15/04/2024
B10: Estado de cuenta
B12: Descripción | C12: Fecha | D12: Débito | E12: Crédito | F12: Saldo
B13: Pago Patricia FACQUET | C13: 45117 | E13: 5900 | F13: =E13 -> 5900
B14: Pago por CH para Patricia FACQUET | C14: 45197 | E14: 3600 | F14: =F13-D14+E14 -> 9500
B15: Pago por CH para Patricia FACQUET | C15: 45229 | E15: 15300 | F15: =F14-D15+E15 -> 24800
B16: Pago por Manon para Patricia FACQUET | C16: 45258 | E16: 46400 | F16: =F15-D16+E16 -> 71200
B17: SALDO ANTERIOR | C17: 45291 | F17: =F16-D17+E17 -> 71200
B18: Pedido de fondo – cuota extraordinaria AGE del 12-01-2024 | C18: 45321 | D18: 12239.9 | F18: =F17-D18+E18 -> 58960.1
B19: Gastos Total año 2023 (Aprobado en AGO del 13 febrero 2024) | C19: 45335 | D19: 63470.2 | F19: =F18-D19+E19 -> -4510.1
B20: Fondo de Reservas 2023 (Pedido del 01/10/2023 - Total $40,000RD) | C20: 45335 | D20: 3142.22 | F20: =F19-D20+E20 -> -7652.32
B21: 1er Trimestre 2024 (Enero – Marzo) / Gastos común provisional | C21: 45336 | D21: 9804.48 | F21: =F20-D21+E21 -> -17456.8
B22: 1er Trimestre 2024 (Enero – Marzo) / Fondo de Reservas 2024 | C22: 45336 | D22: 785.56 | F22: =F21-D22+E22 -> -18242.36
B23: Pago Patricia FACQUET | C23: 45342 | E23: 12230 | F23: =F22-D23+E23 -> -6012.36
B24: Pago Patricia FACQUET | C24: 45359 | E24: 6015 | F24: =F23-D24+E24 -> 2.64
B25: 2do Trimestre 2024 (Abril – Junio) / Gastos común provisional | C25: 45397 | D25: 9804.48 | F25: =F24-D25+E25 -> -9801.84
B26: 2do Trimestre 2024 (Abril – Junio) / Fondo de Reservas 2024 | C26: 45397 | D26: 785.555 | F26: =F25-D26+E26 -> -10587.395
B27: Pedido de fondo – cuota extraordinaria Voto electronico del 09-04-2024 | C27: 45397 | D27: 6163.1818 | F27: =F26-D27+E27 -> -16750.577
B28: Pago Patricia FACQUET | C28: 45415 | E28: 16750.58 | F28: =F27-D28+E28 -> 0.0031610352
B29: 3er Trimestre 2024 (Julio– Septiembre) / Gastos común provisional | C29: 45474 | D29: ='Presupuesto 2024 Aprobado'!C53 -> 9804.48 | F29: =F28-D29+E29 -> -9804.4768
B30: 3er Trimestre 2024 (Julio– Septiembre) / Fondo de Reservas 2024 | C30: 45474 | D30: ='Presupuesto 2024 Aprobado'!D53 -> 785.555 | F30: =F29-D30+E30 -> -10590.032
C31: TOTAL A4-FACQUET | D31: =SUM(D13:D30) -> 116785.61 | E31: =SUM(E13:E30) -> 106195.58 | F31: =E31-D31 -> -10590.032
B33: Nota Importante:
B34: Su estado de cuenta está en manera provisional hasta que se cierran las contabilidades del 2024.
B36: Banco POPULAR
B37: Cuenta Corriente - Sra YUNAIRY ENCARNACION - Cedula 134-0005411-3
B38: Cuenta : 0839787280
B39: Pesos

Sheet A5
A3: CONDOMINIO EL FRAMBOYANT
A4: Calle 30 de Marzo, Las Terrenas, Samaná, República Dominicana 32200
B5: Apartamento A-5
B6: Gernot ENGEL | D6: Fecha limite de pago : 17.07.24
B7: gernot.engel2@gmail.com
G9: Periodo de 01/01/2024 hasta 15/04/2024
B10: Estado de cuenta
B12: Descripción | C12: Fecha | D12: Débito | E12: Crédito | F12: Saldo
B13: Pago Gernot ENGEL | C13: 45117 | E13: 5900 | F13: =E13 -> 5900
B14: Pago Gernot ENGEL | C14: 45117 | E14: 4425 | F14: =F13-D14+E14 -> 10325
B15: Pago Gernot ENGEL | C15: 45208 | E15: 18821 | F15: =F14-D15+E15 -> 29146
B16: Pago Gernot ENGEL | C16: 45245 | E16: 57225 | F16: =F15-D16+E16 -> 86371
B17: SALDO ANTERIOR | C17: 45291 | F17: =F16-D17+E17 -> 86371
B18: Pedido de fondo – cuota extraordinaria AGE del 12-01-2024 | C18: 45321 | D18: 15084.59 | F18: =F17-D18+E18 -> 71286.41
B19: Gastos Total año 2023 (Aprobado en AGO del 13 febrero 2024) | C19: 45335 | D19: 78221.4 | F19: =F18-D19+E19 -> -6934.99
B20: Fondo de Reservas 2023 (Pedido del 01/10/2023 - Total $40,000RD) | C20: 45335 | D20: 3872.51 | F20: =F19-D20+E20 -> -10807.5
B21: 1er Trimestre 2024 (Enero – Marzo) / Gastos común provisional | C21: 45336 | D21: 12083.15 | F21: =F20-D21+E21 -> -22890.65
B22: 1er Trimestre 2024 (Enero – Marzo) / Fondo de Reservas 2024 | C22: 45336 | D22: 968.13 | F22: =F21-D22+E22 -> -23858.78
B23: Pago Gernot ENGEL | C23: 45336 | E23: 15000 | F23: =F22-D23+E23 -> -8858.78
B24: Pago Gernot ENGEL | C24: 45358 | E24: 8900 | F24: =F23-D24+E24 -> 41.22
B25: 2do Trimestre 2024 (Abril – Junio) / Gastos común provisional | C25: 45397 | D25: 12083.153 | F25: =F24-D25+E25 -> -12041.932
B26: 2do Trimestre 2024 (Abril – Junio) / Fondo de Reservas 2024 | C26: 45397 | D26: 968.1275 | F26: =F25-D26+E26 -> -13010.06
B27: Pedido de fondo – cuota extraordinaria Voto electronico del 09-04-2024 | C27: 45397 | D27: 7562.5516 | F27: =F26-D27+E27 -> -20572.612
B28: Pago Gernot ENGEL | C28: 45404 | E28: 18600 | F28: =F27-D28+E28 -> -1972.6116
B29: Pago Gernot ENGEL | C29: 45414 | E29: 2000 | F29: =F28-D29+E29 -> 27.388372
B30: 3er Trimestre 2024 (Julio– Septiembre) / Gastos común provisional | C30: 45474 | D30: ='Presupuesto 2024 Aprobado'!C54 -> 12083.153 | F30: =F29-D30+E30 -> -12055.764
B31: 3er Trimestre 2024 (Julio– Septiembre) / Fondo de Reservas 2024 | C31: 45474 | D31: ='Presupuesto 2024 Aprobado'!D54 -> 968.1275 | F31: =F30-D31+E31 -> -13023.892
C32: TOTAL A5-ENGER | D32: =SUM(D13:D31) -> 143894.89 | E32: =SUM(E13:E31) -> 130871 | F32: =E32-D32 -> -13023.892
B34: Nota Importante:
B35: Su estado de cuenta está en manera provisional hasta que se cierran las contabilidades del 2024.
B37: Banco POPULAR
B38: Cuenta Corriente - Sra YUNAIRY ENCARNACION - Cedula 134-0005411-3
B39: Cuenta : 0839787280
B40: Pesos

Sheet A6
A3: CONDOMINIO EL FRAMBOYANT
A4: Calle 30 de Marzo, Las Terrenas, Samaná, República Dominicana 32200
B5: Apartamento A-6
B6: Inversiones Ter 187, eirl / Karina SANTOS | D6: Fecha limite de pago : 17.07.24
B7: skangelical77@gmail.com
G9: Periodo de 01/01/2024 hasta 15/04/2024
B10: Estado de cuenta
B12: Descripción | C12: Fecha | D12: Débito | E12: Crédito | F12: Saldo
B13: Pago Karina SANTOS | C13: 45117 | E13: 5900 | F13: =E13 -> 5900
B14: Pago Karina SANTOS | C14: 45117 | E14: 7272 | F14: =F13-D14+E14 -> 13172
B15: Pago Karina SANTOS | C15: 45217 | E15: 30925 | F15: =F14-D15+E15 -> 44097
B16: Pago Karina SANTOS | C16: 45246 | E16: 94010 | F16: =F15-D16+E16 -> 138107
B17: SALDO ANTERIOR | C17: 45291 | F17: =F16-D17+E17 -> 138107
B18: Pedido de fondo – cuota extraordinaria AGE del 12-01-2024 | C18: 45321 | D18: 24786.23 | F18: =F17-D18+E18 -> 113320.77
B19: Pago Karina SANTOS | C19: 45334 | E19: 24787 | F19: =F18-D19+E19 -> 138107.77
B20: Gastos Total año 2023 (Aprobado en AGO del 13 febrero 2024) | C20: 45335 | D20: 128529.47 | F20: =F19-D20+E20 -> 9578.3
B21: Fondo de Reservas 2023 (Pedido del 01/10/2023 - Total $40,000RD) | C21: 45335 | D21: 6363.12 | F21: =F20-D21+E21 -> 3215.18
B22: 1er Trimestre 2024 (Enero – Marzo) / Gastos común provisional | C22: 45336 | D22: 19854.43 | F22: =F21-D22+E22 -> -16639.25
B23: 1er Trimestre 2024 (Enero – Marzo) / Fondo de Reservas 2024 | C23: 45336 | D23: 1590.78 | F23: =F22-D23+E23 -> -18230.03
B24: Pago Karina SANTOS | C24: 45358 | E24: 18230.03 | F24: =F23-D24+E24 -> 0
B25: 2do Trimestre 2024 (Abril – Junio) / Gastos común provisional | C25: 45397 | D25: 19854.428 | F25: =F24-D25+E25 -> -19854.428
B26: 2do Trimestre 2024 (Abril – Junio) / Fondo de Reservas 2024 | C26: 45397 | D26: 1590.78 | F26: =F25-D26+E26 -> -21445.208
B27: Pedido de fondo – cuota extraordinaria Voto electronico del 09-04-2024 | C27: 45397 | D27: 12426.404 | F27: =F26-D27+E27 -> -33871.611
B28: Pago Karina SANTOS | C28: 45412 | E28: 33871.61 | F28: =F27-D28+E28 -> -0.0012309679
B29: 3er Trimestre 2024 (Julio– Septiembre) / Gastos común provisional | C29: 45474 | D29: ='Presupuesto 2024 Aprobado'!C55 -> 19854.428 | F29: =F28-D29+E29 -> -19854.429
B30: 3er Trimestre 2024 (Julio– Septiembre) / Fondo de Reservas 2024 | C30: 45474 | D30: ='Presupuesto 2024 Aprobado'!D55 -> 1590.78 | F30: =F29-D30+E30 -> -21445.209
C31: TOTAL A6-SANTOS | D31: =SUM(D13:D30) -> 236440.85 | E31: =SUM(E13:E30) -> 214995.64 | F31: =E31-D31 -> -21445.209
B33: Nota Importante:
B34: Su estado de cuenta está en manera provisional hasta que se cierran las contabilidades del 2024.
B36: Banco POPULAR
B37: Cuenta Corriente - Sra YUNAIRY ENCARNACION - Cedula 134-0005411-3
B38: Cuenta : 0839787280
B39: Pesos

Sheet A7
A3: CONDOMINIO EL FRAMBOYANT
A4: Calle 30 de Marzo, Las Terrenas, Samaná, República Dominicana 32200
B5: Apartamento A-7
B6: Jonathan & Stacy HAZELTINE | D6: Fecha limite de pago : 17.07.24
B7: jon@sweetspot.property
G9: Periodo de 01/01/2024 hasta 15/04/2024
B10: Estado de cuenta
B12: Descripción | C12: Fecha | D12: Débito | E12: Crédito | F12: Saldo
B13: Pago HAZELTINE | C13: 45110 | E13: 11424 | F13: =E13 -> 11424
B14: Pago HAZELTINE | C14: 45117 | E14: 5900 | F14: =F13-D14+E14 -> 17324
B15: Pago HAZELTINE | C15: 45203 | E15: 48596 | F15: =F14-D15+E15 -> 65920
B16: Pago HAZELTINE | C16: 45252 | E16: 147723.95 | F16: =F15-D16+E16 -> 213643.95
B17: SALDO ANTERIOR | C17: 45291 | F17: =F16-D17+E17 -> 213643.95
B18: Pedido de fondo – cuota extraordinaria AGE del 12-01-2024 | C18: 45321 | D18: 38949.11 | F18: =F16-D18+E18 -> 174694.84
B19: Gastos Total año 2023 (Aprobado en AGO del 13 febrero 2024) | C19: 45335 | D19: 201971.36 | F19: =F18-D19+E19 -> -27276.52
B20: Fondo de Reservas 2023 (Pedido del 01/10/2023 - Total $40,000RD) | C20: 45335 | D20: 9999.01 | F20: =F19-D20+E20 -> -37275.53
B21: 1er Trimestre 2024 (Enero – Marzo) / Gastos común provisional | C21: 45336 | D21: 31199.27 | F21: =F20-D21+E21 -> -68474.8
B22: 1er Trimestre 2024 (Enero – Marzo) / Fondo de Reservas 2024 | C22: 45336 | D22: 2499.75 | F22: =F21-D22+E22 -> -70974.55
B23: Pago HAZELTINE | C23: 45338 | E23: 44170.7 | F23: =F22-D23+E23 -> -26803.85
B24: Pago HAZELTINE (26,803.85 + 5,221.59) | C24: 45343 | E24: 26803.85 | F24: =F23-D24+E24 -> 3.6379788e-11
B25: 2do Trimestre 2024 (Abril – Junio) / Gastos común provisional | C25: 45397 | D25: 31199.272 | F25: =F24-D25+E25 -> -31199.272
B26: 2do Trimestre 2024 (Abril – Junio) / Fondo de Reservas 2024 | C26: 45397 | D26: 2499.7525 | F26: =F25-D26+E26 -> -33699.025
B27: Pedido de fondo – cuota extraordinaria Voto electronico del 09-04-2024 | C27: 45397 | D27: 19526.866 | F27: =F26-D27+E27 -> -53225.891
B28: Pago HAZELTINE | C28: 45411 | E28: 53225.89 | F28: =F27-D28+E28 -> -0.00059066035
B29: 3er Trimestre 2024 (Julio– Septiembre) / Gastos común provisional | C29: 45474 | D29: ='Presupuesto 2024 Aprobado'!C56 -> 31199.272 | F29: =F28-D29+E29 -> -31199.273
B30: 3er Trimestre 2024 (Julio– Septiembre) / Fondo de Reservas 2024 | C30: 45474 | D30: ='Presupuesto 2024 Aprobado'!D56 -> 2499.7525 | F30: =F29-D30+E30 -> -33699.026
C31: TOTAL A7-HAZELTINE | D31: =SUM(D13:D30) -> 371543.42 | E31: =SUM(E13:E30) -> 337844.39 | F31: =F24-D31+E31 -> -33699.026
B36: Nota Importante:
B37: Su estado de cuenta está en manera provisional hasta que se cierran las contabilidades del 2024.
B39: Banco POPULAR
B40: Cuenta Corriente - Sra YUNAIRY ENCARNACION - Cedula 134-0005411-3
B41: Cuenta : 0839787280
B42: Pesos

Sheet Distribución
K1: 26236200
B2: Propietario | C2: Unidad | E2: Superficie | F2: Porcentaje | J2: Unidad | K2: Valor RD$ | L2: Repartición % | M2: Repartición % | N2: Repartición
B3: Serge GUERRIN | C3: A-1 | J3: 1 | K3: =K1/J20*J13 -> 3385038.8 | L3: 12.9 | M3: 12.9 | N3: =M3*10000 -> 129000
C4: Apartamento | D4: SP-01-01-001 | E4: 79.09 | J4: 2 | K4: =K1/J20*J14 -> 3452215.8 | L4: 13.16 | M4: 13.16 | N4: =M4*10000 -> 131600
C5: Terraza | D5: SE-01-01-001 | E5: 18.91 | J5: 3 | K5: =K1/J20*J15 -> 4062206.5 | L5: 15.48 | M5: 15.48 | N5: =M5*10000 -> 154800
C6: Jardín | D6: SE-01-01-002 | E6: 71.31 | J6: 4 | K6: =K1/J20*J16 -> 2069290.2 | L6: 7.89 | M6: 7.89 | N6: =M6*10000 -> 78900
E7: =SUM(E4:E6) -> 169.31 | F7: =E7/E44 -> 0.12902169 | G7: 0.129 | J7: 5 | K7: =K1/J20*J17 -> 2539129 | L7: 9.68 | M7: 9.68 | N7: =M7*10000 -> 96800
B8: Herve METAYER | C8: A-2 | J8: 6 | K8: =K1/J20*J18 -> 4172168.8 | L8: 15.9 | M8: 15.9 | N8: =M8*10000 -> 159000
C9: Apartamento | D9: SP-01-01-002 | E9: 90.48 | J9: 7 | K9: =K1/J20*J19 -> 6556151 | L9: 24.99 | M9: 24.99 | N9: =M9*10000 -> 249900
C10: Terraza | D10: SE-01-01-003 | E10: 24.52 | K10: =SUM(K3:K9) -> 26236200 | L10: =SUM(L3:L9) -> 100 | M10: =SUM(M3:M9) -> 100 | N10: =SUM(N3:N9) -> 1000000
C11: Jardín | D11: SE-01-01-004 | E11: 57.67
E12: =SUM(E9:E11) -> 172.67 | F12: =E12/E44 -> 0.13158216 | G12: 0.1316 | I12: Unidad | J12: M2 | K12: Total Unidad | L12: Votos | M12: Votos | N12: Votos
B13: Frédéric ONDELLA | C13: A-3 | I13: 1 | J13: 169.31 | K13: 1 | L13: 0.9031 | M13: 0.9031 | N13: =M13*10000 -> 9031
C14: Apartamento | D14: SP-01-01-003 | E14: 82.55 | I14: 2 | J14: 172.67 | K14: 1 | L14: 0.9211 | M14: 0.9211 | N14: =M14*10000 -> 9211
C15: Terraza | D15: SE-01-01-005 | E15: 25.38 | I15: 3 | J15: 203.18 | K15: 1 | L15: 1.0838 | M15: 1.0838 | N15: =M15*10000 -> 10838
C16: Terraza | D16: SE-01-01-006 | E16: 4.57 | I16: 4 | J16: 103.5 | K16: 1 | L16: 0.5521 | M16: 0.5521 | N16: =M16*10000 -> 5521
C17: Jardín | D17: SE-01-01-007 | E17: 90.68 | I17: 5 | J17: 127 | K17: 1 | L17: 0.6775 | M17: 0.6775 | N17: =M17*10000 -> 6775
E18: =SUM(E14:E17) -> 203.18 | F18: =E18/E44 -> 0.15483212 | G18: 0.1548 | I18: 6 | J18: 208.68 | K18: 1 | L18: 1.1132 | M18: 1.1132 | N18: =M18*10000 -> 11132
B19: Patricia FACQUET | C19: A-4 | I19: 7 | J19: 327.92 | K19: 1 | L19: 1.7492 | M19: 1.7492 | N19: =M19*10000 -> 17492
C20: Apartamento | D20: SP-01-02-001 | E20: 72.59 | J20: =J13+J14+J15+J16+J17+J18+J19 -> 1312.26 | K20: =SUM(K13:K19) -> 7 | L20: =SUM(L13:L19) -> 7 | M20: =SUM(M13:M19) -> 7 | N20: =SUM(N13:N19) -> 70000
C21: Terraza | D21: SE-01-02-001 | E21: 18.91
C22: Parqueo | D22: SE-00-01-002 | E22: 12
E23: =SUM(E20:E22) -> 103.5 | F23: =E23/E44 -> 0.078871565 | G23: 0.0789 | I23: 1 | J23: 169.31 | K23: 1312.26 | L23: 0.129021 | M23: 7 | N23: =L23*M23 -> 0.903147
B24: Gernot ENGER | C24: A-5 | I24: 2 | J24: 172.67 | K24: 1312.26 | L24: 0.131582 | M24: 7 | N24: =L24*M24 -> 0.921074
C25: Apartamento | D25: SP-01-02-002 | E25: 90.48 | I25: 3 | J25: 203.18 | K25: 1312.26 | L25: =J25/K25 -> 0.15483212 | M25: 7 | N25: =L25*M25 -> 1.0838249
C26: Terraza | D26: SE-01-02-002 | E26: 24.52 | I26: 4 | J26: 103.5 | K26: 1312.26 | L26: =J26/K26 -> 0.078871565 | M26: 7 | N26: =L26*M26 -> 0.55210096
C27: Parqueo | D27: SE-00-01-003 | E27: 12 | I27: 5 | J27: 127 | K27: 1312.26 | L27: =J27/K27 -> 0.096779602 | M27: 7 | N27: =L27*M27 -> 0.67745721
E28: =SUM(E25:E27) -> 127 | F28: =E28/E44 -> 0.096779602 | G28: 0.0968 | I28: 6 | J28: 208.68 | K28: 1312.26 | L28: =J28/K28 -> 0.15902336 | M28: 7 | N28: =L28*M28 -> 1.1131635
B29: Inversiones Ter 187 eirl (Karina SANTOS) | C29: A-6 | I29: 7 | J29: 327.92 | K29: 1312.26 | L29: =J29/K29 -> 0.2498895 | M29: 7 | N29: =L29*M29 -> 1.7492265
C30: Apartamento | D30: SP-01-02-003 | E30: 82.55 | J30: =SUM(J23:J29) -> 1312.26 | L30: =SUM(L23:L29) -> 0.99999916 | N30: =SUM(N23:N29) -> 6.9999941
C31: Terraza | D31: SE-01-02-003 | E31: 25.38
C32: Terraza | D32: SE-01-02-004 | E32: 4.57
C33: Parqueo | D33: SE-00-01-004 | E33: 12
C34: Jardín | D34: SE-01-01-008 | E34: 72.46
C35: Escalera | D35: SE-01-01-009 | E35: 6.37
C36: Escalera | D36: SE-01-02-005 | E36: 5.35
E37: =SUM(E30:E36) -> 208.68 | F37: =E37/E44 -> 0.15902336 | G37: 0.159
B38: Jonathan HAZELTINE | C38: A-7
C39: Apartamento | D39: SP-01-03-001 | E39: 123.26
C40: Terraza | D40: SE-01-03-001 | E40: 176.74
...
