Workbook

Sheet Fondo de reservas
B3: CONDOMINIO EL FRAMBOYANT
B4: Calle 30 de Marzo, Las Terrenas, Samaná, República Dominicana 32200
G6: Periodo de 01/01 hasta 31/12/2025
C7: FONDO DE RESERVAS
C9: Descripción | D9: Fecha | E9: Tipo | F9: Debito | G9: Credito
C10: Saldo balance al 31/12/2024 | D10: 45658 | E10: BQ | G10: 19751.87
C11: Deposito- Compra bomba sumergible | D11: 45678 | E11: BQ | G11: 36205.11
E22: TOTAL | F22: =SUBTOTAL(109,F10:F21) -> 0 | G22: =SUBTOTAL(109,G10:G21) -> 55956.98
C24: TOTAL DÉBITO | F24: =F22 -> 0
C25: TOTAL CRÉDITO | G25: =G22 -> 55956.98
C26: BALANCE AL DÍA | G26: =G25+F24 -> 55956.98

Sheet Caja Chica-Cta.Bco
A3: CONDOMINIO EL FRAMBOYANT | H3: CONDOMINIO EL FRAMBOYANT
A4: Calle 30 de Marzo, Las Terrenas, Samaná, República Dominicana 32200 | H4: Calle 30 de Marzo, Las Terrenas, Samaná, República Dominicana 32200
F6: Periodo de 01/01 hasta 31/12/2025 | M6: Periodo de 01/01 hasta 31/12/2025
B7: Estado CAJA CHICA | I7: Estado Cuenta Bancaria/ Banco Popular
B9: Descripción | C9: Fecha | D9: Tipo | E9: Debito | F9: Credito | I9: Descripción | J9: Fecha | K9: Tipo | L9: Debito | M9: Credito
B10: Saldo balance al 31/12/2024 | C10: 45658 | D10: CA | F10: 14920 | I10: Saldo balance al 31/12/2024 | J10: 45658 | K10: BQ | M10: 6280.94
B11: Mano de obra y chequeo bomba sumergible | C11: 45660 | D11: CA | E11: -6700 | I11: CARGO MENSual TD clasica | J11: 45659 | K11: BQ | L11: -65
B12: Yile-Limpieza profunda de locales de basura y safacones | C12: 45660 | D12: CA | E12: -1150 | I12: Pago SANTOS – A6 | J12: 45677 | K12: BQ | M12: 31999.57
B13: Yile- Limpieza de Zafacones | C13: 45666 | D13: CA | E13: -700 | I13: Pago GUERIN – A1 | J13: 45680 | K13: BQ | M13: 16108.65
B14: Elias Batista- Limpieza y recogida de basura en el framboyan y el canal | C14: 45672 | D14: CA | E14: -4000
B15: Reparacion tubo septico,materiales y mano de obra | C15: 45675 | D15: CA | E15: -1200 | I15: Cargo por servicio Generado | J15: 45680 | K15: BQ | L15: -65
B16: Pago ENGEL – A5 | C16: 45678 | F16: 19500 | I16: Yile jardinero-limpieza de casitas basura, bomba,parqueo,desagues y escalera | J16: 45681 | K16: BQ | L16: -2500
B17: Pago HAZELTINE – A7 | C17: 45678 | F17: 53300 | I17: Luz y Fuerza-Diciembre 2024 | J17: 45685 | K17: BQ | L17: -822.82
B18: Pago METAYER-JEAN- A2 | C18: 45679 | D18: CA | F18: 16200 | I18: Inapa Diciembre y Enero | J18: 45685 | K18: BQ | L18: -7200
B19: Pago ONDELLA – A3 | C19: 45680 | D19: CA | F19: 34510 | I19: Andre Lora- Recogida basura Diciembre y enero | J19: 45685 | K19: BQ | L19: -2000
B20: Elia-Limpieza caños de entrada A1/2/#3 | C20: 45685 | D20: CA | E20: -4000 | I20: Completivo Honorarios Administrador (Enero-2025) | J20: 45687 | L20: -6000
B21: Cargo administrador recordatorio pago 15 dias despues venc.Pedido de fondo – cuota extraordinaria Voto electronico del 11-10-2024. y 09.12.24 + pedido excepional enero-25( cargo A1 ) | C21: 45685 | D21: CA | E21: -1000 | I21: Impuesto 0.15% DGII | J21: 45688 | K21: BQ | L21: -13.8
B22: Honorario administrador Enero 2025 | C22: 45687 | D22: CA | E22: -9000 | I22: CARGO MENSual TD clasica | J22: 45691 | K22: BQ | L22: -65
B23: Deposito a Cuenta Banco | C23: 45694 | D23: CA | E23: -66000 | I23: Pago Cuota poliza seguro 01CO-185 | J23: 45693 | K23: BQ | L23: -39598.89
B24: Elias Batista- Limpieza Mata de palma y recogida de basura | C24: 45700 | D24: CA | E24: -2000 | I24: Deposito desde Caja chica | J24: 45694 | K24: BQ | M24: 66000
B25: Elias Batista- Limpieza De porton | C25: 45702 | D25: CA | E25: -800 | I25: Adelanto 60% inscripcion al RNC condominio Framboyant | J25: 45695 | K25: BQ | L25: -18600
I26: Impuesto 0.15% DGII | J26: 45695 | K26: BQ | L26: -59.4
I27: Impuesto 0.15% DGII | J27: 45702 | K27: BQ | L27: -27.9
I28: Pago FACQUET – A4 | J28: 45706 | K28: BQ | M28: 15862.34
I29: Impuesto 0.15% DGII | J29: 45706 | K29: BQ | L29: -65
I30: Pago final 40% inscripcion al Rnc Condominio | J30: 45713 | K30: BQ | L30: -12400
I31: Impuesto 0.15% DGII | J31: 45716 | K31: BQ | L31: -18.6
I32: Luz y Fuerza-Enero 2025 | J32: 45716 | K32: BQ | L32: -755.55
I33: Inapa Febrero | J33: 45716 | K33: BQ | L33: -3600
I34: Andre Lora- Recogida basura Febrero 2025 | J34: 45716 | K34: BQ | L34: -1000
D37: TOTAL | E37: =SUBTOTAL(109,E10:E25) -> -96550 | F37: =SUBTOTAL(109,F10:F23) -> 138430 | K37: TOTAL | L37: =SUM(L10:L36) -> -94856.96 | M37: =SUM(M10:M36) -> 136251.5
B39: TOTAL DÉBITO | E39: =E37 -> -96550 | I39: TOTAL DÉBITO | L39: =L37 -> -94856.96
B40: TOTAL CRÉDITO | F40: =F37 -> 138430 | I40: TOTAL CRÉDITO | M40: =M37 -> 136251.5
B41: BALANCE AL DÍA | F41: =F40+E39 -> 41880 | I41: BALANCE AL DÍA | M41: =M40+L39 -> 41394.54
B43: Saldo banco | C43: 45747 | F43: =M41 -> 41394.54
B44: Saldo efectivo | C44: 45747 | F44: =F41 -> 41880
C45: TOTAL BALANCE AL DÍA | F45: =SUM(F43:F44) -> 83274.54
E46: Fondo de Reservas | F46: ='Fondo de reservas'!G26 -> 55956.98
E47: BALANCE DISPONIBLE PARA GASTOS: | F47: =F45-F46 -> 27317.56
D49: Serge GUERRIN | E49: A-1 | F49: ='A1'!F66 -> -51847.853 | G49: En debito
...

Sheet Gastos detallados
A3: CONDOMINIO EL FRAMBOYANT
A4: Calle 30 de Marzo, Las Terrenas, Samaná, República Dominicana 32200
E6: Periodo de 01/01 hasta 31/12/2025
B7: Estado detallados de gastos
B9: INAPA (Contrato 321528) / Agua | C9: Fecha | D9: Monto
B10: INAPA Diciembre 2024 y Enero 2025 | C10: 45685 | D10: 7200
B11: INAPA Febrero 2025 | C11: 45716 | D11: 3600
B13: Total | D13: =SUM(D10:D12) -> 10800
B15: LUZ Y FUERZA / Electricidad | C15: Fecha | D15: Monto
B16: Luz Diciembre 2024 (95 kwh) | C16: 45685 | D16: 822.82
B17: Luz Enero 2025 (86 kwh) | C17: 45716 | D17: 755.55
B19: Total | D19: =SUM(D16:D18) -> 1578.37
B21: Cargos Bancario / Banco Popular | C21: Fecha | D21: Monto
B22: CARGO MENSual TD clasica | C22: 45659 | D22: 65
B23: Cargo por servicio Generado | C23: 45680 | D23: 65
B24: Impuesto 0.15% DGII | C24: 45688 | D24: 13.8
B25: CARGO MENSual TD clasica | C25: 45691 | D25: 65
B26: Impuesto 0.15% DGII | C26: 45695 | D26: 59.4
B27: Impuesto 0.15% DGII | C27: 45702 | D27: 27.9
B28: Impuesto 0.15% DGII | C28: 45706 | D28: 65
B29: Impuesto 0.15% DGII | C29: 45716 | D29: 18.6
B35: Total | D35: =SUM(D22:D34) -> 379.7
B37: Reparaciones / Mantenimientos | C37: Fecha | D37: Monto
B38: Mano de obra y chequeo bomba sumergible | C38: 45660 | D38: 6700
B39: Yile jardinero-limpieza de casitas basura, bomba,parqueo,desagues y escalera | C39: 45681 | D39: 2500
B43: Total | D43: =SUM(D38:D39) -> 9200
B45: Seguro Incendio y R.C. | C45: Fecha | D45: Monto
B46: Seguro Incendio + RC (Universal)
B47: Total | D47: =SUM(D46) -> 0
B49: Basura / Recogida mensual | C49: Fecha | D49: Monto
B50: Recogida basura Diciembre 2024 y Enero 2025 | C50: 45685 | D50: 2000
B51: Recogida basura Febrero 2025 | C51: 45716 | D51: 1000
B55: Total | D55: =SUM(D50:D54) -> 3000
B57: Honorarios del Administrador | C57: Fecha | D57: Monto
B58: Honorario administrador Diciembre 2025 | C58: 45658 | D58: 15000
B59: Honorario administrador Enero 2025 | C59: 45687 | D59: 15000
B63: Total | D63: =SUM(D58:D62) -> 30000
B65: Honorarios del Administrador (Extras) | C65: Fecha | D65: Monto
B70: Total | D70: =SUM(D66:D69) -> 0
B72: Honorarios por servicios profesionales | C72: Fecha | D72: Monto
...

Sheet A1
A3: CONDOMINIO EL FRAMBOYANT
A4: Calle 30 de Marzo, Las Terrenas, Samaná, República Dominicana 32200
B5: Apartamento A-1
B6: Serge GUERIN | C6: Fecha limite de pago : 28 de marzo a las 4.00 pm
B7: serge47.guerin@gmail.com
G9: Periodo de 01/01/2025 hasta 06/03/2025
B10: Estado de cuenta
B12: Descripción | C12: Fecha | D12: Débito | E12: Crédito | F12: Saldo
B13: Pago Serge GUERIN | C13: 45331 | E13: 47720.9 | F13: =E13 -> 47720.9
B14: Pago Serge GUERIN | C14: 45339 | E14: 35005.6 | F14: =F13-D14+E14 -> 82726.5
B15: Rectificación error del 09/02/2024 | C15: 45343 | E15: 72.56 | F15: =F14-D15+E15 -> 82799.06
B16: Pago Serge GUERIN | C16: 45510 | E16: 17400 | F16: =F15-D16+E16 -> 100199.06
B17: Pago Serge GUERIN | C17: 45572 | E17: 16108.65 | F17: =F16-D17+E17 -> 116307.71
B18: Cargo 2% del $26 548.93 (Reglamento Art.33-d) | C18: 45297 | D18: 530.98 | F18: =F17-D18+E18 -> 115776.73
B19: Honorario del Alguacil LT para la Notificación de deudas | C19: 45330 | D19: 4000 | F19: =F18-D19+E19 -> 111776.73
B20: Cargo 2% del $10,082.01 (Reglamento Art.33-d) | C20: 45418 | D20: 201.64 | F20: =F19-D20+E20 -> 111575.09
B21: Cargo administrador recordatorio pago 15 dias despues venc.Pedido de fondo – cuota extraordinaria Voto electronico del 09-04-2024 $10,082.01 | C21: 45418 | D21: 1000 | F21: =F20-D21+E21 -> 110575.09
B22: Cargo 2% de $24,574 (Reglamento Art.33-d)Age 12.01.24 orden 6 | C22: 45443 | D22: 491.48 | F22: =F21-D22+E22 -> 110083.61
B23: Cargo administrador recordatorio pago 15 dias despues venc Cuota diff presupuesto gastos reales 12.01.24 - Orden6) | C23: 45443 | D23: 1000 | F23: =F22-D23+E23 -> 109083.61
B24: Cargo 2% del $10,082.01 (Reglamento Art.33-d) voto del 09.04.24 | C24: 45449 | D24: 201.64 | F24: =F23-D24+E24 -> 108881.97
B25: Cargo 2% de $24,574 (Reglamento Art.33-d)Age 12.01.24 orden 6 | C25: 45473 | D25: 491.48 | F25: =F24-D25+E25 -> 108390.49
B26: Cargo administrador segundo recordatorio pago 45 dias despues venc. (Pedido 2do Trimiestre Abril-Junio 2024 | C26: 45473 | D26: 3000 | F26: =F25-D26+E26 -> 105390.49
B27: Cargo administrador segundo recordatorio pago 45 dias despues venc. (Cuota diff presupuesto gastos reales 12.01.24 - Orden6) | C27: 45473 | D27: 3000 | F27: =F26-D27+E27 -> 102390.49
B28: Cargo 2% del $10,082.01 (Reglamento Art.33-d) voto del 09.04.24 | C28: 45479 | D28: 201.64 | F28: =F27-D28+E28 -> 102188.85
B29: Honorarios Alguacil-Notificacion de pago | C29: 45481 | D29: 5000 | F29: =F28-D29+E29 -> 97188.85
... B49: Cargo 2% de $24,574 (Reglamento Art.33-d)Diff Presupuesto pared cerca | C49: 45656 | D49: 491.48 | F49: =F48-D49+E49 -> 91063.42
B50: Gastos Total año 2024 (Aprobado en AGO del 01 de marzo) | D50: 111381.5 | F50: =F49-D50+E50 -> -20318.08
B51: BALANCE AL 31/12/2024 | C51: 45658 | F51: =F50 -> -20318.08
B52: Pedido de fondo – cuota extraordinaria Voto electronico del 11-10-2024 | C52: 45664 | D52: 6072.3928 | F52: =F50-D52+E52 -> -26390.473
B53: Pedido de fondo – cuota extraordinaria Voto electronico del 09-12-2024 | C53: 45664 | D53: 14452.816 | F53: =F52-D53+E53 -> -40843.289
B54: Pedido Excepcional- Enero 2025 | C54: 45664 | D54: 5445.3745 | F54: =F53-D54+E54 -> -46288.663
B55: Pago Serge GUERIN | C55: 45680 | E55: 16108.65 | F55: =F54-D55+E55 -> -30180.013
B56: 1er Trimestre 2025 (Enero – Marzo) / Gastos común provisional | C56: 45730 | D56: 17667.84 | F56: =F55-D56+E56 -> -47847.853
C57: TOTAL A1-GUERRIN | D57: =SUM(D13:D56) -> 180264.21 | E57: =SUM(E13:E56) -> 132416.36 | F57: =E57-D57 -> -47847.853
B60: GASTOS PRIVADO - Aparte de los gastos comunes
B61: Cargo administrador recordatorio pago 15 dias despues venc.Pedido de fondo – cuota extraordinaria Voto electronico del 11-10-2024. y 09.12.24 + pedido excepional enero-25 | C61: 45685 | D61: -1000
B62: Cargo administrador segundo recordatorio pago 45 dias despues venc. ( cuota extraordinaria Voto electronico del 11-10-2024. y 09.12.24 + pedido excepional enero-25) | C62: 45716 | D62: -3000
B64: total | D64: =SUM(D61:D62) -> -4000
F66: =F57+D64 -> -51847.853
B67: Nota Importante: | F67: TOTAL en debito
...

Sheet A2
A3: CONDOMINIO EL FRAMBOYANT
A4: Calle 30 de Marzo, Las Terrenas, Samaná, República Dominicana 32200
B5: Apartamento A-2
B6: Hervé METAYER / Corine JEAN | D6: Fecha limite de pago : 28 de marzo a las 4.00 pm
B7: hmetayer.business@gmail.com; corine.2021@outlook.fr
G9: Periodo de 01/01/2025 hasta 06/03/2025
B10: Estado de cuenta
B12: Descripción | C12: Fecha | D12: Débito | E12: Crédito | F12: Saldo
B13: Pago METAYER-JEAN | C13: 45342 | E13: 38625 | F13: =E13 -> 38625
B14: Pago METAYER-JEAN | C14: 45408 | E14: 22556.56 | F14: =F13-D14+E14 -> 61181.56
B15: Pago METAYER-JEAN | C15: 45488 | E15: 18000 | F15: =F14-D15+E15 -> 79181.56
B16: Pago METAYER-JEAN | C16: 45531 | E16: 12400 | F16: =F15-D16+E16 -> 91581.56
B17: Pago METAYER-JEAN | C17: 45581 | E17: 18025 | F17: =F16-D17+E17 -> 109606.56
B18: Pago METAYER-JEAN | C18: 45621 | E18: 10000 | F18: =F17-D18+E18 -> 119606.56
B19: Cargo MoneyGram/Deposito Banco-Gasto Personal-A2 | C19: 45342 | D19: 1000 | F19: =F18-D19+E19 -> 118606.56
B20: Cargo MoneyGram/Deposito Banco | C20: 45408 | D20: 1000 | F20: =F19-D20+E20 -> 117606.56
B21: Gastos Total año 2024 (Aprobado en AGO del 01 de marzo) | D21: 113626.4 | F21: =F20-D21+E21 -> 3980.16
B22: BALANCE AL 31/12/2024 | C22: 45658 | F22: =F21 -> 3980.16
B23: Pedido de fondo – cuota extraordinaria Voto electronico del 11-10-2024 | C23: 45664 | D23: 6192.901 | F23: =F21-D23+E23 -> -2212.741
B24: Pedido de fondo – cuota extraordinaria Voto electronico del 09-12-2024 | C24: 45664 | D24: 14739.636 | F24: =F23-D24+E24 -> -16952.377
B25: Pedido Excepcional- Enero 2025 | C25: 45664 | D25: 5553.4394 | F25: =F24-D25+E25 -> -22505.816
B26: Pago METAYER-JEAN | C26: 45679 | E26: 16200 | F26: =F25-D26+E26 -> -6305.8161
B27: 1er Trimestre 2025 (Enero – Marzo) / Gastos común provisional | C27: 45730 | D27: 18023.94 | F27: =F26-D27+E27 -> -24329.756
B28: Cuota Extraordinaria - Inscripcion de privilegio contra unidad A1 | C28: 45730 | D28: 13950 | F28: =F27-D28 -> -38279.756
C29: TOTAL A2-METAYER | D29: =SUM(D13:D28) -> 174086.32 | E29: =SUM(E13:E28) -> 135806.56 | F29: =E29-D29 -> -38279.756
B30: Nota Importante:
B31: Su estado de cuenta está en manera provisional hasta que se cierran las contabilidades del 2025.
B33: Banco POPULAR
B34: Cuenta Corriente - Sra YUNAIRY ENCARNACION - Cedula 134-0005411-3
B35: Cuenta : 0839787280
B36: Pesos

Sheet A3
A3: CONDOMINIO EL FRAMBOYANT
A4: Calle 30 de Marzo, Las Terrenas, Samaná, República Dominicana 32200
B5: Apartamento A3
B6: Frédéric ONDELLA | D6: Fecha limite de pago : 28 de marzo a las 4.00 pm
B7: ondellaf@yahoo.fr
G9: Periodo de 01/01/2025 hasta 06/03/2025
B10: Estado de cuenta
B12: Descripción | C12: Fecha | D12: Débito | E12: Crédito | F12: Saldo
B13: Pago Frédéric ONDELLA | C13: 45335 | E13: 24134 | F13: =E13 -> 24134
B14: Pago Frédéric ONDELLA | C14: 45358 | E14: 17600 | F14: =F13-D14+E14 -> 41734
B15: Pago Frédéric ONDELLA | C15: 45412 | E15: 33000 | F15: =F14-D15+E15 -> 74734
B16: Pago Frédéric ONDELLA | C16: 45490 | E16: 20900 | F16: =F15-D16+E16 -> 95634
B17: Pago Frédéric ONDELLA | C17: 45534 | E17: 11100 | F17: =F16-D17+E17 -> 106734
B18: Pago Frédéric ONDELLA | C18: 45570 | E18: 21000 | F18: =F17-D18+E18 -> 127734
B19: COMPRA DE 3 CAMION DE AGUA, fuga de agua flotador tinaco A-3 | C19: 45597 | D19: 3000 | F19: =F18-D19+E19 -> 124734
B20: COMPRA DE MEDIO CAMION DE AGUA, fuga de agua flotador tinaco A-3 | C20: 45608 | D20: 500 | F20: =F19-D20+E20 -> 124234
B21: Gastos Total año 2024 (Aprobado en AGO del 01 de marzo) | D21: 133657.8 | F21: =F20-D21+E21 -> -9423.8
B22: SALDO ANTERIOR BALANCE AL 31/12/2024 | C22: 45658 | F22: =F21 -> -9423.8
B23: Pedido de fondo – cuota extraordinaria Voto electronico del 11-10-2024 | C23: 45664 | D23: 7287.1583 | F23: =F21-D23+E23 -> -16710.958
B24: Pedido de fondo – cuota extraordinaria Voto electronico del 09-12-2024 | C24: 45664 | D24: 17344.062 | F24: =F23-D24+E24 -> -34055.02
B25: Pedido Excepcional- Enero 2025 | C25: 45664 | D25: 6534.7067 | F25: =F24-D25+E25 -> -40589.727
B26: Pago Frédéric ONDELLA | C26: 45680 | E26: 34510 | F26: =F25-D26+E26 -> -6079.7271
B27: 1er Trimestre 2025 (Enero – Marzo) / Gastos común provisional | C27: 45730 | D27: 21201.41 | F27: =F26-D27+E27 -> -27281.137
B28: Cuota Extraordinaria - Inscripcion de privilegio contra unidad A1 | C28: 45730 | D28: 16740 | F28: =F27-D28 -> -44021.137 | H28: =44050+E26 -> 78560
B29: TOTAL A-3 FREDERIC ONDELLA | D29: =SUM(D13:D28) -> 206265.14 | E29: =SUM(E13:E28) -> 162244 | F29: =E29-D29 -> -44021.137
B32: Nota Importante:
B33: Su estado de cuenta está en manera provisional hasta que se cierran las contabilidades del 2025
B35: Banco POPULAR
B36: Cuenta Corriente - Sra YUNAIRY ENCARNACION - Cedula 134-0005411-3
B37: Cuenta : 0839787280
B38: Pesos

Sheet A4
A3: CONDOMINIO EL FRAMBOYANT
A4: Calle 30 de Marzo, Las Terrenas, Samaná, República Dominicana 32200
B5: Apartamento A-4
B6: Patricia FACQUET | D6: Fecha limite de pago : 28 de marzo a las 4.00 pm
B7: patriciafacquet@icloud.com
G9: Periodo de 01/01/202 hasta 06/03/2025
B10: Estado de cuenta
B12: Descripción | C12: Fecha | D12: Débito | E12: Crédito | F12: Saldo
B13: Pago Patricia FACQUET | C13: 45342 | E13: 12230 | F13: =E13 -> 12230
B14: Pago por CH para Patricia FACQUET | C14: 45359 | E14: 6015 | F14: =F13-D14+E14 -> 18245
B15: Pago por CH para Patricia FACQUET | C15: 45415 | E15: 16750.58 | F15: =F14-D15+E15 -> 34995.58
B16: Pago por Manon para Patricia FACQUET | C16: 45488 | E16: 10600 | F16: =F15-D16+E16 -> 45595.58
B17: Pago por Manon para Patricia FACQUET | C17: 45534 | E17: 5650 | F17: =F16-D17+E17 -> 51245.58
B18: Pago por Manon para Patricia FACQUET | C18: 45586 | E18: 10600 | F18: =F17-D18+E18 -> 61845.58
B19: Gastos Total año 2024 (Aprobado en AGO DEL 01 de marzo) | D19: 68124.03 | F19: =F18-D19+E19 -> -6278.45
B20: SALDO ANTERIOR BALANCE AL 31/12/2024 | C20: 45658 | F20: =F19 -> -6278.45
B21: Pedido de fondo – cuota extraordinaria Voto electronico del 11-10-2024 | C21: 45664 | D21: 3712.0823 | F21: =F19-D21+E21 -> -9990.5323
B22: Pedido de fondo – cuota extraordinaria Voto electronico del 09-12-2024 | C22: 45664 | D22: 8835.0744 | F22: =F21-D22+E22 -> -18825.607
B23: Pedido Excepcional- Enero 2025 | C23: 45664 | D23: 3328.7831 | F23: =F22-D23+E23 -> -22154.39
B24: Pago Patricia FACQUET | C24: 45706 | E24: 15862.34 | F24: =F23-D24+E24 -> -6292.0498
B25: 1er Trimestre 2025 (Enero – Marzo) / Gastos común provisional | C25: 45730 | D25: 10806.14 | F25: =F24-D25+E25 -> -17098.19
B26: Cuota Extraordinaria - Inscripcion de privilegio contra unidad A1 | C26: 45730 | D26: 8370 | F26: =F25-D26 -> -25468.19
C27: TOTAL A4-FACQUET | D27: =SUM(D13:D26) -> 103176.11 | E27: =SUM(E13:E26) -> 77707.92 | F27: =E27-D27 -> -25468.19
B29: Nota Importante:
B30: Su estado de cuenta está en manera provisional hasta que se cierran las contabilidades del 2025.
B32: Banco POPULAR
B33: Cuenta Corriente - Sra YUNAIRY ENCARNACION - Cedula 134-0005411-3
B34: Cuenta : 0839787280
B35: Pesos

Sheet A5
A3: CONDOMINIO EL FRAMBOYANT
A4: Calle 30 de Marzo, Las Terrenas, Samaná, República Dominicana 32200
B5: Apartamento A-5
B6: Gernot ENGEL | D6: Fecha limite de pago : 28 de marzo a las 4.00 pm
B7: gernot.engel2@gmail.com
G9: Periodo de 01/01/2025 hasta 06/03/2025
B10: Estado de cuenta
B12: Descripción | C12: Fecha | D12: Débito | E12: Crédito | F12: Saldo
B13: Pago Gernot ENGEL | C13: 45336 | E13: 15000 | F13: =E13 -> 15000
B14: Pago Gernot ENGEL | C14: 45358 | E14: 8900 | F14: =F13-D14+E14 -> 23900
B15: Pago Gernot ENGEL | C15: 45404 | E15: 18600 | F15: =F14-D15+E15 -> 42500
B16: Pago Gernot ENGEL | C16: 45414 | E16: 2000 | F16: =F15-D16+E16 -> 44500
B17: Pago Gernot ENGEL | C17: 45488 | E17: 13025 | F17: =F16-D17+E17 -> 57525
B18: Pago Gernot ENGEL | C18: 45527 | E18: 7000 | F18: =F17-D18+E18 -> 64525
B19: Pago Gernot ENGEL | C19: 45576 | E19: 13000 | F19: =F18-D19+E19 -> 77525
B20: Gastos Total año 2024 (Aprobado en AGO) | D20: 83579.3 | F20: =F19-D20+E20 -> -6054.3
B21: SALDO ANTERIOR BALANCE AL 31/12/2024 | C21: 45658 | F21: =F20 -> -6054.3
B22: Pedido de fondo – cuota extraordinaria Voto electronico del 11-10-2024 | C22: 45664 | D22: 4554.9223 | F22: =F20-D22+E22 -> -10609.222
B23: Pedido de fondo – cuota extraordinaria Voto electronico del 09-12-2024 | C23: 45664 | D23: 10841.106 | F23: =F22-D23+E23 -> -21450.328
B24: Pedido Excepcional- Enero 2025 | C24: 45664 | D24: 4084.5937 | F24: =F23-D24+E24 -> -25534.922
B25: Pago Gernot ENGEL | C25: 45678 | E25: 19500 | F25: =F24-D25+E25 -> -6034.9218
B26: 1er Trimestre 2025 (Enero – Marzo) / Gastos común provisional | C26: 45730 | D26: 13257.73 | F26: =F25-D26+E26 -> -19292.652
B27: Cuota Extraordinaria - Inscripcion de privilegio contra unidad A1 | C27: 45730 | D27: 10230 | F27: =F26-D27 -> -29522.652
C28: TOTAL A5-ENGER | D28: =SUM(D13:D27) -> 126547.65 | E28: =SUM(E13:E27) -> 97025 | F28: =E28-D28 -> -29522.652
B30: Nota Importante:
B31: Su estado de cuenta está en manera provisional hasta que se cierran las contabilidades del 2025
B33: Banco POPULAR
B34: Cuenta Corriente - Sra YUNAIRY ENCARNACION - Cedula 134-0005411-3
B35: Cuenta : 0839787280
B36: Pesos

Sheet A6
A3: CONDOMINIO EL FRAMBOYANT
A4: Calle 30 de Marzo, Las Terrenas, Samaná, República Dominicana 32200
B5: Apartamento A-6
B6: Inversiones Ter 187, eirl / Karina SANTOS | D6: Fecha limite de pago : 28 de marzo a las 4.00 pm
B7: skangelical77@gmail.com
G9: Periodo de 01/01/2025 hasta 06/03/2025
B10: Estado de cuenta
B12: Descripción | C12: Fecha | D12: Débito | E12: Crédito | F12: Saldo
B13: Pago Karina SANTOS | C13: 45334 | E13: 24787 | F13: =E13 -> 24787
B14: Pago Karina SANTOS | C14: 45358 | E14: 18230.03 | F14: =F13-D14+E14 -> 43017.03
B15: Pago Karina SANTOS | C15: 45412 | E15: 33871.61 | F15: =F14-D15+E15 -> 76888.64
B16: Pago Karina SANTOS | C16: 45484 | E16: 21445.21 | F16: =F15-D16+E16 -> 98333.85
B17: Pago Karina SANTOS | C17: 45530 | E17: 11404.47 | F17: =F16-D17+E17 -> 109738.32
B18: Pago Karina SANTOS | C18: 45579 | E18: 21455.21 | F18: =F17-D18+E18 -> 131193.53
B19: Gastos Total año 2024 (Aprobado en AGO) | D19: 137284.18 | F19: =F18-D19+E19 -> -6090.65
B20: SALDO ANTERIOR BALANCE AL 31/12/2024 | C20: 45658 | F20: =F19 -> -6090.65
B21: Pedido de fondo – cuota extraordinaria Voto electronico del 11-10-2024 | C21: 45664 | D21: 7484.4187 | F21: =F19-D21+E21 -> -13575.069
B22: Pedido de fondo – cuota extraordinaria Voto electronico del 09-12-2024 | C22: 45664 | D22: 17813.559 | F22: =F21-D22+E22 -> -31388.627
B23: Pedido Excepcional- Enero 2025 | C23: 45664 | D23: 6711.5986 | F23: =F22-D23+E23 -> -38100.226
B24: Pago Karina SANTOS | C24: 45677 | E24: 31999.57 | F24: =F23-D24+E24 -> -6100.656
B25: 1er Trimestre 2025 (Enero – Marzo) / Gastos común provisional | C25: 45730 | D25: 21776.64 | F25: =F24-D25+E25 -> -27877.296
B26: Cuota Extraordinaria - Inscripcion de privilegio contra unidad A1 | C26: 45730 | D26: 16740 | F26: =F25-D26 -> -44617.296
C27: TOTAL A6-SANTOS | D27: =SUM(D13:D26) -> 207810.4 | E27: =SUM(E13:E26) -> 163193.1 | F27: =E27-D27 -> -44617.296
B29: Nota Importante:
B30: Su estado de cuenta está en manera provisional hasta que se cierran las contabilidades del 2025
B32: Banco POPULAR
B33: Cuenta Corriente - Sra YUNAIRY ENCARNACION - Cedula 134-0005411-3
B34: Cuenta : 0839787280
B35: Pesos

Sheet A7
A3: CONDOMINIO EL FRAMBOYANT
A4: Calle 30 de Marzo, Las Terrenas, Samaná, República Dominicana 32200
B5: Apartamento A-7
B6: Jonathan & Stacy HAZELTINE | D6: Fecha limite de pago : 28 de marzo a las 4.00 pm
B7: jon@sweetspot.property
G9: Periodo de 01/01/2025 hasta 06/03/2025
B10: Estado de cuenta
B12: Descripción | C12: Fecha | D12: Débito | E12: Crédito | F12: Saldo
B13: Pago HAZELTINE | C13: 45338 | E13: 44170.7 | F13: =E13 -> 44170.7
B14: Pago HAZELTINE | C14: 45343 | E14: 26803.85 | F14: =F13-D14+E14 -> 70974.55
B15: Pago HAZELTINE | C15: 45411 | E15: 53225.89 | F15: =F14-D15+E15 -> 124200.44
B16: Pago HAZELTINE | C16: 45488 | E16: 33699.03 | F16: =F15-D16+E16 -> 157899.47
B17: Pago HAZELTINE | C17: 45528 | E17: 17921 | F17: =F16-D17+E17 -> 175820.47
B18: Pago HAZELTINE | C18: 45570 | E18: 33699.02 | F18: =F17-D18+E18 -> 209519.49
B19: COMPRA DE 1 CAMION DE AGUA, fuga de agua lavamano segundo piso | C19: 45614 | D19: 1000 | F19: =F18-D19+E19 -> 208519.49
B20: COMPRA DE 1 CAMION DE AGUA, fuga de agua | C20: 45645 | D20: 1000 | F20: =F19-D20+E20 -> 207519.49
B21: COMPRA DE 1 CAMION DE AGUA, fuga de agua | C21: 45647 | D21: 1000 | F21: =F20-D21+E21 -> 206519.49
B22: Gastos Total año 2024 (Aprobado en AGO) | D22: 215769.28 | F22: =F21-D22+E22 -> -9249.79
B23: SALDO ANTERIOR BALANCE AL 31/12/2024 | C23: 45658 | F23: =F22 -> -9249.79
B24: Pedido de fondo – cuota extraordinaria Voto electronico del 11-10-2024 | C24: 45664 | D24: 11761.024 | F24: =F22-D24+E24 -> -21010.814
B25: Pedido de fondo – cuota extraordinaria Voto electronico del 09-12-2024 | C25: 45664 | D25: 27992.247 | F25: =F24-D25+E25 -> -49003.062
B26: Pedido Excepcional- Enero 2025 | C26: 45664 | D26: 10546.614 | F26: =F25-D26+E26 -> -59549.676
B27: Pago HAZELTINE | C27: 45678 | E27: 53300 | F27: =F26-D27+E27 -> -6249.6758
B28: 1er Trimestre 2025 (Enero – Marzo) / Gastos común provisional | C28: 45722 | D28: 34226.3 | F28: =F27-D28+E28 -> -40475.976
B29: Cuota Extraordinaria - Inscripcion de privilegio contra unidad A1 | C29: 45730 | D29: 26970 | F29: =F28-D29 -> -67445.976
C30: TOTAL A7-HAZELTINE | D30: =SUM(D13:D29) -> 330265.47 | E30: =SUM(E13:E29) -> 262819.49 | F30: =E30-D30 -> -67445.976
B32: Nota Importante:
B33: Su estado de cuenta está en manera provisional hasta que se cierran las contabilidades del 2025.
B35: Banco POPULAR
B36: Cuenta Corriente - Sra YUNAIRY ENCARNACION - Cedula 134-0005411-3
B37: Cuenta : 0839787280
B38: Pesos

Sheet Pedido Exceptional - ENERO2025
A3: CONDOMINIO EL FRAMBOYANT
A4: Calle 30 de Marzo, Las Terrenas, Samaná, República Dominicana 32200
B7: Pedido de fondo para trabajos emergencia 2025
E9: Total
B10: Compra de Bomba de agua sumergible+ Materiales | E10: 36205.11
B12: Compra de 6 Camiones de agua (Averia inapa) | E12: 6000
D14: Monto total | E14: =SUM(E10:E13) -> 42205.11
B15: Notas;
B16: Esta cuota extraordinaria es la manera provisional (presupuestos).
B17: La cierre contable del ejercicio 2024 concluirá una vez que se apruebe en la Asamblea General
B18: Ordinaria del principio 2025.
B20: Les pedimos de realizar su pago lo antes posible.
B21: Les recordamos que tiene 15 días de pagar, en contrario 2% de mora será aplicado.
B23: Repartición de Cuota Extraordianaria - Enero 2025 | E23: =E14 -> 42205.11 | H23: Unidad | I23: Total monto | J23: Valor RD$ | K23: Total valor RD$ | L23: Repartición % | M23: Monto/cada
B24: Propietario | C24: UNIDAD | D24: % | E24: Monto a pagar | H24: 1 | I24: =E23 -> 42205.11 | J24: 3385038.8 | K24: 26236200 | L24: =J24/J31*100 -> 12.902169 | M24: =(I24*J24/K24) -> 5445.3745 | N24: =M24 -> 5445.3745
B25: Serge GUERRIN | C25: A-1 | D25: 0.129 | E25: =M24 -> 5445.3745 | H25: 2 | I25: =E23 -> 42205.11 | J25: 3452215.8 | K25: 26236200 | L25: =J25/J31*100 -> 13.158216 | M25: =(I25*J25/K25) -> 5553.4394 | N25: =M25 -> 5553.4394
B26: JEAN-METAYER | C26: A-2 | D26: 0.1316 | E26: =M25 -> 5553.4394 | H26: 3 | I26: =E23 -> 42205.11 | J26: 4062206.5 | K26: 26236200 | L26: =J26/J31*100 -> 15.483212 | M26: =(I26*J26/K26) -> 6534.7067 | N26: =M26 -> 6534.7067
B27: Frédéric ONDELLA | C27: A-3 | D27: 0.1548 | E27: =M26 -> 6534.7067 | H27: 4 | I27: =E23 -> 42205.11 | J27: 2069290.2 | K27: 26236200 | L27: =J27/J31*100 -> 7.8871565 | M27: =(I27*J27/K27) -> 3328.7831 | N27: =M27 -> 3328.7831
B28: Patricia FACQUET | C28: A-4 | D28: 0.0789 | E28: =M27 -> 3328.7831 | H28: 5 | I28: =E23 -> 42205.11 | J28: 2539129 | K28: 26236200 | L28: =J28/J31*100 -> 9.6779602 | M28: =(I28*J28/K28) -> 4084.5937 | N28: =M28 -> 4084.5937
B29: Gernot ENGER | C29: A-5 | D29: 0.0968 | E29: =M28 -> 4084.5937 | H29: 6 | I29: =E23 -> 42205.11 | J29: 4172168.8 | K29: 26236200 | L29: =J29/J31*100 -> 15.902336 | M29: =(I29*J29/K29) -> 6711.5986 | N29: =M29 -> 6711.5986
B30: Inversiones Ter 187 eirl (Karina SANTOS) | C30: A-6 | D30: 0.159 | E30: =M29 -> 6711.5986 | H30: 7 | I30: =E23 -> 42205.11 | J30: 6556151 | K30: 26236200 | L30: =J30/J31*100 -> 24.98895 | M30: =(I30*J30/K30) -> 10546.614 | N30: =M30 -> 10546.614
B31: Jonathan HAZELTINE | C31: A-7 | D31: 0.2499 | E31: =M30 -> 10546.614 | J31: =SUM(J24:J30) -> 26236200 | L31: =SUM(L24:L30) -> 100 | M31: =SUM(M24:M30) -> 42205.11 | N31: =SUM(N24:N30) -> 42205.11
B32: Total | D32: =SUM(D25:D31) -> 1 | E32: =SUM(E25:E31) -> 42205.11

Sheet Cuota Extraordinaria Privilegio
A3: CONDOMINIO EL FRAMBOYANT
A4: Calle 30 de Marzo, Las Terrenas, Samaná, República Dominicana 32200
B7: Cuota Extraordinaria - Inscripcion de privilegio contra unidad A1
E8: Total
B9: Inscripcion de Privilegio en el Registro de Titulo de Samana | E9: 93000
D11: Monto total | E11: =SUM(E9:E10) -> 93000
B12: Notas;
B13: Esta cuota extraordinaria es la manera provisional (presupuestos). Esta al cargo unico del copropietario moroso, y los otros copropietarios estaran reembolsado en cuando se cobra la deuda de unidad A1
B14: La cierre contable del ejercicio 2025 concluirá una vez que se apruebe en la Asamblea General
B15: Ordinaria del principio 2026.
B17: Les pedimos de realizar su pago lo antes posible.
B18: Les recordamos que tiene 15 días de pagar, en contrario 2% de mora será aplicado.
B20: Repartición de Cuota Extraordinaria - Inscripcion de privilegio contra unidad A1 | E20: 93000
B21: Propietario | C21: UNIDAD | D21: % sin A1 | E21: Monto a pagar
B22: Serge GUERRIN | C22: A-1
B23: JEAN-METAYER | C23: A-2 | D23: 0.15 | E23: =E20*D23 -> 13950
B24: Frédéric ONDELLA | C24: A-3 | D24: 0.18 | E24: =E20*D24 -> 16740
B25: Patricia FACQUET | C25: A-4 | D25: 0.09 | E25: =E20*D25 -> 8370
B26: Gernot ENGER | C26: A-5 | D26: 0.11 | E26: =E20*D26 -> 10230
B27: Inversiones Ter 187 eirl (Karina SANTOS) | C27: A-6 | D27: 0.18 | E27: =E20*D27 -> 16740
B28: Jonathan HAZELTINE | C28: A-7 | D28: 0.29 | E28: =E20*D28 -> 26970
B29: Total | D29: =SUM(D22:D28) -> 1 | E29: =SUM(E22:E28) -> 93000
B34: Unidad | C34: Total monto | D34: Valor RD$ | E34: Total valor RD$ | F34: Repartición % | G34: Reparticion sin A1
B35: 1 | C35: =E20 -> 93000 | D35: 3385038.8 | E35: 26236200
B36: 2 | C36: =E20 -> 93000 | D36: 3452215.8 | E36: 26236200 | F36: =D36/D42*100 -> 13.158216 | G36: 0.15 | H36: =C36*G36 -> 13950
B37: 3 | C37: =E20 -> 93000 | D37: 4062206.5 | E37: 26236200 | F37: =D37/D42*100 -> 15.483212 | G37: 0.18 | H37: =C37*G37 -> 16740
B38: 4 | C38: =E20 -> 93000 | D38: 2069290.2 | E38: 26236200 | F38: =D38/D42*100 -> 7.8871565 | G38: 0.09 | H38: =C38*G38 -> 8370
B39: 5 | C39: =E20 -> 93000 | D39: 2539129 | E39: 26236200 | F39: =D39/D42*100 -> 9.6779602 | G39: 0.11 | H39: =C39*G39 -> 10230
B40: 6 | C40: =E20 -> 93000 | D40: 4172168.8 | E40: 26236200 | F40: =D40/D42*100 -> 15.902336 | G40: 0.18 | H40: =C40*G40 -> 16740
B41: 7 | C41: =E20 -> 93000 | D41: 6556151 | E41: 26236200 | F41: =D41/D42*100 -> 24.98895 | G41: 0.29 | H41: =C41*G41 -> 26970
D42: =SUM(D35:D41) -> 26236200 | F42: =SUM(F35:F41) -> 87.097831 | G42: =SUM(G35:G41) -> 1 | H42: =SUM(H35:H41) -> 93000

Sheet Presupuesto 2025 Aprobado
A2: CONDOMINIO EL FRAMBOYANT
A3: Calle 30 de Marzo, Las Terrenas, Samaná, República Dominicana 32200
F5: Periodo de 01/01 hasta 31/12/2025
B6: Presupuesto Provisional 2025
C8: Por mes | D8: Meses | E8: Anual
B9: INAPA/Agua | C9: 3600 | D9: 12 | E9: =C9*D9 -> 43200
B10: Agua (camión de agua) | C10: 2500 | D10: 12 | E10: =C10*D10 -> 30000
B11: LUZ Y FUERZA / Electricidad | C11: 850 | D11: 12 | E11: =C11*D11 -> 10200
B12: Jardinero-Limpieza casitas basuras+ casita bomba | C12: 2500 | D12: 12 | E12: =C12*D12 -> 30000
B13: Reparaciones / Mantenimientos | C13: 3500 | D13: 12 | E13: =C13*D13 -> 42000
B14: Basura / Recogida mensual | C14: 1000 | D14: 12 | E14: =C14*D14 -> 12000
B15: Honorario Administrador | C15: 18000 | D15: 12 | E15: =C15*D15 -> 216000
B16: Gastos bancario | C16: 170 | D16: 12 | E16: =C16*D16 -> 2040
B17: Seguro Incendio y R.C. (20/11/2024-2025) | C17: 13533.33 | D17: 12 | E17: 162400
B18: Total Anual Gastos Provisional 2025 | C18: =SUM(C9:C17) -> 45653.33 | E18: =SUM(E9:E17) -> 547840
B20: Se pedirá trimestralmente (4 veces) : 136,960.00
H22: Calculo presupuesto 2025
B23: Repartición de gasto común provisional 2025: | D23: por año | E23: =E18 -> 547840 | H23: Unidad | I23: Total monto | J23: Valor RD$ | K23: Total valor RD$ | L23: Repartición % | M23: Monto/cada
B24: Propietario | C24: UNIDAD | D24: % | E24: Monto a pagar | H24: 1 | I24: =E23 -> 547840 | J24: 3386200 | K24: 26236200 | L24: =(J24/J31)*100 -> 12.906595 | M24: =(I24*J24/K24) -> 70707.488
B25: Serge GUERRIN | C25: A-1 | D25: 0.129 | E25: =547840*D25 -> 70671.36 | H25: 2 | I25: =E23 -> 547840 | J25: 3453400 | K25: 26236200 | L25: =(J25/J31)*100 -> 13.162729 | M25: =(I25*J25/K25) -> 72110.697
B26: Herve METAYER | C26: A-2 | D26: 0.1316 | E26: =547840*D26 -> 72095.744 | H26: 3 | I26: =E23 -> 547840 | J26: 4063600 | K26: 26236200 | L26: =(J26/J31)*100 -> 15.488523 | M26: =(I26*J26/K26) -> 84852.327
B27: Frédéric ONDELLA | C27: A-3 | D27: 0.1548 | E27: =547840*D27 -> 84805.632 | H27: 4 | I27: =E23 -> 547840 | J27: 2061000 | K27: 26236200 | L27: =(J27/J31)*100 -> 7.8555584 | M27: =(I27*J27/K27) -> 43035.891
B28: Patricia FACQUET | C28: A-4 | D28: 0.0789 | E28: =547840*D28 -> 43224.576 | H28: 5 | I28: =E23 -> 547840 | J28: 2540000 | K28: 26236200 | L28: =(J28/J31)*100 -> 9.6812801 | M28: =(I28*J28/K28) -> 53037.925
B29: Gernot ENGER | C29: A-5 | D29: 0.0968 | E29: =547840*D29 -> 53030.912 | H29: 6 | I29: =E23 -> 547840 | J29: 4173600 | K29: 26236200 | L29: =(J29/J31)*100 -> 15.907792 | M29: =(I29*J29/K29) -> 87149.245
B30: Inversiones Ter 187 eirl (Karina SANTOS) | C30: A-6 | D30: 0.159 | E30: =547840*D30 -> 87106.56 | H30: 7 | I30: =E23 -> 547840 | J30: 6558400 | K30: 26236200 | L30: =(J30/J31)*100 -> 24.997523 | M30: =(I30*J30/K30) -> 136946.43
B31: Jonathan HAZELTINE | C31: A-7 | D31: 0.2499 | E31: =547840*D31 -> 136905.22 | J31: =SUM(J24:J30) -> 26236200 | L31: =SUM(L24:L30) -> 100 | M31: =SUM(M24:M30) -> 547840
B32: Total | D32: =SUM(D25:D31) -> 1 | E32: =SUM(E25:E31) -> 547840
C35: MONTO TRIMESTRE 2025
B36: Unidad | C36: Gastos | E36: Total
B37: A-1 | C37: =E25/4 -> 17667.84 | E37: =C37+D37 -> 17667.84
B38: A-2 | C38: =E26/4 -> 18023.936 | E38: =C38+D38 -> 18023.936
B39: A-3 | C39: =E27/4 -> 21201.408 | E39: =C39+D39 -> 21201.408
B40: A-4 | C40: =E28/4 -> 10806.144 | E40: =C40+D40 -> 10806.144
B41: A-5 | C41: =E29/4 -> 13257.728 | E41: =C41+D41 -> 13257.728
B42: A-6 | C42: =E30/4 -> 21776.64 | E42: =C42+D42 -> 21776.64
B43: A-7 | C43: =E31/4 -> 34226.304 | E43: =C43+D43 -> 34226.304
C44: =SUM(C37:C43) -> 136960 | D44: =SUM(D37:D43) -> 0 | E44: =SUM(E37:E43) -> 136960

Sheet Distribución
K1: 26236200
B2: Propietario | C2: Unidad | E2: Superficie | F2: Porcentaje | J2: Unidad | K2: Valor RD$ | L2: Repartición % | M2: Repartición % | N2: Repartición
B3: Serge GUERRIN | C3: A-1 | J3: 1 | K3: =K1/J20*J13 -> 3385038.8 | L3: 12.9 | M3: 12.9 | N3: =M3*10000 -> 129000
C4: Apartamento | D4: SP-01-01-001 | E4: 79.09 | J4: 2 | K4: =K1/J20*J14 -> 3452215.8 | L4: 13.16 | M4: 13.16 | N4: =M4*10000 -> 131600
C5: Terraza | D5: SE-01-01-001 | E5: 18.91 | J5: 3 | K5: =K1/J20*J15 -> 4062206.5 | L5: 15.48 | M5: 15.48 | N5: =M5*10000 -> 154800
C6: Jardín | D6: SE-01-01-002 | E6: 71.31 | J6: 4 | K6: =K1/J20*J16 -> 2069290.2 | L6: 7.89 | M6: 7.89 | N6: =M6*10000 -> 78900
E7: =SUM(E4:E6) -> 169.31 | F7: =E7/E44 -> 0.12902169 | G7: 0.129 | J7: 5 | K7: =K1/J20*J17 -> 2539129 | L7: 9.68 | M7: 9.68 | N7: =M7*10000 -> 96800
B8: Herve METAYER | C8: A-2 | J8: 6 | K8: =K1/J20*J18 -> 4172168.8 | L8: 15.9 | M8: 15.9 | N8: =M8*10000 -> 159000
C9: Apartamento | D9: SP-01-01-002 | E9: 90.48 | J9: 7 | K9: =K1/J20*J19 -> 6556151 | L9: 24.99 | M9: 24.99 | N9: =M9*10000 -> 249900
C10: Terraza | D10: SE-01-01-003 | E10: 24.52 | K10: =SUM(K3:K9) -> 26236200 | L10: =SUM(L3:L9) -> 100 | M10: =SUM(M3:M9) -> 100 | N10: =SUM(N3:N9) -> 1000000
C11: Jardín | D11: SE-01-01-004 | E11: 57.67
E12: =SUM(E9:E11) -> 172.67 | F12: =E12/E44 -> 0.13158216 | G12: 0.1316 | I12: Unidad | J12: M2 | K12: Total Unidad | L12: Votos | M12: Votos | N12: Votos
B13: Frédéric ONDELLA | C13: A-3 | I13: 1 | J13: 169.31 | K13: 1 | L13: 0.9031 | M13: 0.9031 | N13: =M13*10000 -> 9031
C14: Apartamento | D14: SP-01-01-003 | E14: 82.55 | I14: 2 | J14: 172.67 | K14: 1 | L14: 0.9211 | M14: 0.9211 | N14: =M14*10000 -> 9211
C15: Terraza | D15: SE-01-01-005 | E15: 25.38 | I15: 3 | J15: 203.18 | K15: 1 | L15: 1.0838 | M15: 1.0838 | N15: =M15*10000 -> 10838
C16: Terraza | D16: SE-01-01-006 | E16: 4.57 | I16: 4 | J16: 103.5 | K16: 1 | L16: 0.5521 | M16: 0.5521 | N16: =M16*10000 -> 5521
C17: Jardín | D17: SE-01-01-007 | E17: 90.68 | I17: 5 | J17: 127 | K17: 1 | L17: 0.6775 | M17: 0.6775 | N17: =M17*10000 -> 6775
E18: =SUM(E14:E17) -> 203.18 | F18: =E18/E44 -> 0.15483212 | G18: 0.1548 | I18: 6 | J18: 208.68 | K18: 1 | L18: 1.1132 | M18: 1.1132 | N18: =M18*10000 -> 11132
B19: Patricia FACQUET | C19: A-4 | I19: 7 | J19: 327.92 | K19: 1 | L19: 1.7492 | M19: 1.7492 | N19: =M19*10000 -> 17492
C20: Apartamento | D20: SP-01-02-001 | E20: 72.59 | J20: =J13+J14+J15+J16+J17+J18+J19 -> 1312.26 | K20: =SUM(K13:K19) -> 7 | L20: =SUM(L13:L19) -> 7 | M20: =SUM(M13:M19) -> 7 | N20: =SUM(N13:N19) -> 70000
C21: Terraza | D21: SE-01-02-001 | E21: 18.91
C22: Parqueo | D22: SE-00-01-002 | E22: 12
E23: =SUM(E20:E22) -> 103.5 | F23: =E23/E44 -> 0.078871565 | G23: 0.0789 | I23: 1 | J23: 169.31 | K23: 1312.26 | L23: 0.129021 | M23: 7 | N23: =L23*M23 -> 0.903147
B24: Gernot ENGER | C24: A-5 | I24: 2 | J24: 172.67 | K24: 1312.26 | L24: 0.131582 | M24: 7 | N24: =L24*M24 -> 0.921074
C25: Apartamento | D25: SP-01-02-002 | E25: 90.48 | I25: 3 | J25: 203.18 | K25: 1312.26 | L25: =J25/K25 -> 0.15483212 | M25: 7 | N25: =L25*M25 -> 1.0838249
C26: Terraza | D26: SE-01-02-002 | E26: 24.52 | I26: 4 | J26: 103.5 | K26: 1312.26 | L26: =J26/K26 -> 0.078871565 | M26: 7 | N26: =L26*M26 -> 0.55210096
C27: Parqueo | D27: SE-00-01-003 | E27: 12 | I27: 5 | J27: 127 | K27: 1312.26 | L27: =J27/K27 -> 0.096779602 | M27: 7 | N27: =L27*M27 -> 0.67745721
E28: =SUM(E25:E27) -> 127 | F28: =E28/E44 -> 0.096779602 | G28: 0.0968 | I28: 6 | J28: 208.68 | K28: 1312.26 | L28: =J28/K28 -> 0.15902336 | M28: 7 | N28: =L28*M28 -> 1.1131635
B29: Inversiones Ter 187 eirl (Karina SANTOS) | C29: A-6 | I29: 7 | J29: 327.92 | K29: 1312.26 | L29: =J29/K29 -> 0.2498895 | M29: 7 | N29: =L29*M29 -> 1.7492265
C30: Apartamento | D30: SP-01-02-003 | E30: 82.55 | J30: =SUM(J23:J29) -> 1312.26 | L30: =SUM(L23:L29) -> 0.99999916 | N30: =SUM(N23:N29) -> 6.9999941
C31: Terraza | D31: SE-01-02-003 | E31: 25.38
C32: Terraza | D32: SE-01-02-004 | E32: 4.57
C33: Parqueo | D33: SE-00-01-004 | E33: 12
C34: Jardín | D34: SE-01-01-008 | E34: 72.46
C35: Escalera | D35: SE-01-01-009 | E35: 6.37
C36: Escalera | D36: SE-01-02-005 | E36: 5.35
E37: =SUM(E30:E36) -> 208.68 | F37: =E37/E44 -> 0.15902336 | G37: 0.159
B38: Jonathan HAZELTINE | C38: A-7
C39: Apartamento | D39: SP-01-03-001 | E39: 123.26
C40: Terraza | D40: SE-01-03-001 | E40: 176.74
...
